Workbook

Sheet Sheet3
A1: ID | D1: 2 | G1: 3 | H1: 4
A2: 4 | B2: =Sheet1!C2+Sheet1!D2+Sheet1!E2+Sheet1!F2+Sheet1!J2+Sheet1!K2+Sheet1!L2+Sheet1!M2 -> 1331.9 | C2: =IF(ISNUMBER(B2),B2,"") -> 1331.9 | D2: =_xlfn.RANK.EQ(C2,$C$2:$C$1031) -> 437 | E2: =Sheet1!C2+Sheet1!D2+Sheet1!E2+Sheet1!F2+Sheet1!J2+Sheet1!K2+Sheet1!L2+Sheet1!M2+Sheet1!Q2+Sheet1!R2+Sheet1!S2+Sheet1!T2 -> 1674.9 | F2: =IF(ISNUMBER(E2),E2,"") -> 1674.9 | G2: =_xlfn.RANK.EQ(F2,$F$2:$F$1031) -> 430 | H2: =INDEX(Sheet1!AD:AD,MATCH(Sheet1!A2,Sheet3!A:A,0)) -> 430
A3: 6 | B3: =Sheet1!C3+Sheet1!D3+Sheet1!E3+Sheet1!F3+Sheet1!J3+Sheet1!K3+Sheet1!L3+Sheet1!M3 -> 1291.5 | C3: =IF(ISNUMBER(B3),B3,"") -> 1291.5 | D3: =_xlfn.RANK.EQ(C3,$C$2:$C$1031) -> 545 | E3: =Sheet1!C3+Sheet1!D3+Sheet1!E3+Sheet1!F3+Sheet1!J3+Sheet1!K3+Sheet1!L3+Sheet1!M3+Sheet1!Q3+Sheet1!R3+Sheet1!S3+Sheet1!T3 -> 1598.5 | F3: =IF(ISNUMBER(E3),E3,"") -> 1598.5 | G3: =_xlfn.RANK.EQ(F3,$F$2:$F$1031) -> 590 | H3: =INDEX(Sheet1!AD:AD,MATCH(Sheet1!A3,Sheet3!A:A,0)) -> 590
A4: 9 | B4: =Sheet1!C4+Sheet1!D4+Sheet1!E4+Sheet1!F4+Sheet1!J4+Sheet1!K4+Sheet1!L4+Sheet1!M4 -> 1452.5 | C4: =IF(ISNUMBER(B4),B4,"") -> 1452.5 | D4: =_xlfn.RANK.EQ(C4,$C$2:$C$1031) -> 40 | E4: =Sheet1!C4+Sheet1!D4+Sheet1!E4+Sheet1!F4+Sheet1!J4+Sheet1!K4+Sheet1!L4+Sheet1!M4+Sheet1!Q4+Sheet1!R4+Sheet1!S4+Sheet1!T4 -> 1838 | F4: =IF(ISNUMBER(E4),E4,"") -> 1838 | G4: =_xlfn.RANK.EQ(F4,$F$2:$F$1031) -> 35 | H4: =INDEX(Sheet1!AD:AD,MATCH(Sheet1!A4,Sheet3!A:A,0)) -> 35
A5: 13 | B5: =Sheet1!C5+Sheet1!D5+Sheet1!E5+Sheet1!F5+Sheet1!J5+Sheet1!K5+Sheet1!L5+Sheet1!M5 -> 941.5 | C5: =IF(ISNUMBER(B5),B5,"") -> 941.5 | D5: =_xlfn.RANK.EQ(C5,$C$2:$C$1031) -> 998 | E5: =Sheet1!C5+Sheet1!D5+Sheet1!E5+Sheet1!F5+Sheet1!J5+Sheet1!K5+Sheet1!L5+Sheet1!M5+Sheet1!Q5+Sheet1!R5+Sheet1!S5+Sheet1!T5 -> 1172.25 | F5: =IF(ISNUMBER(E5),E5,"") -> 1172.25 | G5: =_xlfn.RANK.EQ(F5,$F$2:$F$1031) -> 972 | H5: =INDEX(Sheet1!AD:AD,MATCH(Sheet1!A5,Sheet3!A:A,0)) -> 972
A6: 15 | B6: =Sheet1!C6+Sheet1!D6+Sheet1!E6+Sheet1!F6+Sheet1!J6+Sheet1!K6+Sheet1!L6+Sheet1!M6 -> 1325.1 | C6: =IF(ISNUMBER(B6),B6,"") -> 1325.1 | D6: =_xlfn.RANK.EQ(C6,$C$2:$C$1031) -> 459 | E6: =Sheet1!C6+Sheet1!D6+Sheet1!E6+Sheet1!F6+Sheet1!J6+Sheet1!K6+Sheet1!L6+Sheet1!M6+Sheet1!Q6+Sheet1!R6+Sheet1!S6+Sheet1!T6 -> 1658.1 | F6: =IF(ISNUMBER(E6),E6,"") -> 1658.1 | G6: =_xlfn.RANK.EQ(F6,$F$2:$F$1031) -> 466 | H6: =INDEX(Sheet1!AD:AD,MATCH(Sheet1!A6,Sheet3!A:A,0)) -> 466
A7: 31 | B7: =Sheet1!C7+Sheet1!D7+Sheet1!E7+Sheet1!F7+Sheet1!J7+Sheet1!K7+Sheet1!L7+Sheet1!M7 -> 1407.1 | C7: =IF(ISNUMBER(B7),B7,"") -> 1407.1 | D7: =_xlfn.RANK.EQ(C7,$C$2:$C$1031) -> 184 | E7: =Sheet1!C7+Sheet1!D7+Sheet1!E7+Sheet1!F7+Sheet1!J7+Sheet1!K7+Sheet1!L7+Sheet1!M7+Sheet1!Q7+Sheet1!R7+Sheet1!S7+Sheet1!T7 -> 1776.1 | F7: =IF(ISNUMBER(E7),E7,"") -> 1776.1 | G7: =_xlfn.RANK.EQ(F7,$F$2:$F$1031) -> 170 | H7: =INDEX(Sheet1!AD:AD,MATCH(Sheet1!A7,Sheet3!A:A,0)) -> 170
A8: 32 | B8: =Sheet1!C8+Sheet1!D8+Sheet1!E8+Sheet1!F8+Sheet1!J8+Sheet1!K8+Sheet1!L8+Sheet1!M8 -> 1354.6 | C8: =IF(ISNUMBER(B8),B8,"") -> 1354.6 | D8: =_xlfn.RANK.EQ(C8,$C$2:$C$1031) -> 370 | E8: =Sheet1!C8+Sheet1!D8+Sheet1!E8+Sheet1!F8+Sheet1!J8+Sheet1!K8+Sheet1!L8+Sheet1!M8+Sheet1!Q8+Sheet1!R8+Sheet1!S8+Sheet1!T8 -> 1723.1 | F8: =IF(ISNUMBER(E8),E8,"") -> 1723.1 | G8: =_xlfn.RANK.EQ(F8,$F$2:$F$1031) -> 315 | H8: =INDEX(Sheet1!AD:AD,MATCH(Sheet1!A8,Sheet3!A:A,0)) -> 315
A9: 34 | B9: =Sheet1!C9+Sheet1!D9+Sheet1!E9+Sheet1!F9+Sheet1!J9+Sheet1!K9+Sheet1!L9+Sheet1!M9 -> 1186.3 | C9: =IF(ISNUMBER(B9),B9,"") -> 1186.3 | D9: =_xlfn.RANK.EQ(C9,$C$2:$C$1031) -> 759 | E9: =Sheet1!C9+Sheet1!D9+Sheet1!E9+Sheet1!F9+Sheet1!J9+Sheet1!K9+Sheet1!L9+Sheet1!M9+Sheet1!Q9+Sheet1!R9+Sheet1!S9+Sheet1!T9 -> 1483.3 | F9: =IF(ISNUMBER(E9),E9,"") -> 1483.3 | G9: =_xlfn.RANK.EQ(F9,$F$2:$F$1031) -> 764 | H9: =INDEX(Sheet1!AD:AD,MATCH(Sheet1!A9,Sheet3!A:A,0)) -> 764
A10: 35 | B10: =Sheet1!C10+Sheet1!D10+Sheet1!E10+Sheet1!F10+Sheet1!J10+Sheet1!K10+Sheet1!L10+Sheet1!M10 -> 1223.7 | C10: =IF(ISNUMBER(B10),B10,"") -> 1223.7 | D10: =_xlfn.RANK.EQ(C10,$C$2:$C$1031) -> 699 | E10: =Sheet1!C10+Sheet1!D10+Sheet1!E10+Sheet1!F10+Sheet1!J10+Sheet1!K10+Sheet1!L10+Sheet1!M10+Sheet1!Q10+Sheet1!R10+Sheet1!S10+Sheet1!T10 -> 1578.2 | F10: =IF(ISNUMBER(E10),E10,"") -> 1578.2 | G10: =_xlfn.RANK.EQ(F10,$F$2:$F$1031) -> 634 | H10: =INDEX(Sheet1!AD:AD,MATCH(Sheet1!A10,Sheet3!A:A,0)) -> 634
A11: 37 | B11: =Sheet1!C11+Sheet1!D11+Sheet1!E11+Sheet1!F11+Sheet1!J11+Sheet1!K11+Sheet1!L11+Sheet1!M11 -> 1458.7 | C11: =IF(ISNUMBER(B11),B11,"") -> 1458.7 | D11: =_xlfn.RANK.EQ(C11,$C$2:$C$1031) -> 27 | E11: =Sheet1!C11+Sheet1!D11+Sheet1!E11+Sheet1!F11+Sheet1!J11+Sheet1!K11+Sheet1!L11+Sheet1!M11+Sheet1!Q11+Sheet1!R11+Sheet1!S11+Sheet1!T11 -> 1835.2 | F11: =IF(ISNUMBER(E11),E11,"") -> 1835.2 | G11: =_xlfn.RANK.EQ(F11,$F$2:$F$1031) -> 41 | H11: =INDEX(Sheet1!AD:AD,MATCH(Sheet1!A11,Sheet3!A:A,0)) -> 41
A12: 38 | B12: =Sheet1!C12+Sheet1!D12+Sheet1!E12+Sheet1!F12+Sheet1!J12+Sheet1!K12+Sheet1!L12+Sheet1!M12 -> 1109.8 | C12: =IF(ISNUMBER(B12),B12,"") -> 1109.8 | D12: =_xlfn.RANK.EQ(C12,$C$2:$C$1031) -> 872 | E12: =Sheet1!C12+Sheet1!D12+Sheet1!E12+Sheet1!F12+Sheet1!J12+Sheet1!K12+Sheet1!L12+Sheet1!M12+Sheet1!Q12+Sheet1!R12+Sheet1!S12+Sheet1!T12 -> 1412.8 | F12: =IF(ISNUMBER(E12),E12,"") -> 1412.8 | G12: =_xlfn.RANK.EQ(F12,$F$2:$F$1031) -> 842 | H12: =INDEX(Sheet1!AD:AD,MATCH(Sheet1!A12,Sheet3!A:A,0)) -> 842
A13: 39 | B13: =Sheet1!C13+Sheet1!D13+Sheet1!E13+Sheet1!F13+Sheet1!J13+Sheet1!K13+Sheet1!L13+Sheet1!M13 -> 1428.2 | C13: =IF(ISNUMBER(B13),B13,"") -> 1428.2 | D13: =_xlfn.RANK.EQ(C13,$C$2:$C$1031) -> 108 | E13: =Sheet1!C13+Sheet1!D13+Sheet1!E13+Sheet1!F13+Sheet1!J13+Sheet1!K13+Sheet1!L13+Sheet1!M13+Sheet1!Q13+Sheet1!R13+Sheet1!S13+Sheet1!T13 -> 1799.2 | F13: =IF(ISNUMBER(E13),E13,"") -> 1799.2 | G13: =_xlfn.RANK.EQ(F13,$F$2:$F$1031) -> 105 | H13: =INDEX(Sheet1!AD:AD,MATCH(Sheet1!A13,Sheet3!A:A,0)) -> 105
... A1031: 2603 | B1031: =Sheet1!C1031+Sheet1!D1031+Sheet1!E1031+Sheet1!F1031+Sheet1!J1031+Sheet1!K1031+Sheet1!L1031+Sheet1!M1031 -> 1202.2 | C1031: =IF(ISNUMBER(B1031),B1031,"") -> 1202.2 | D1031: =_xlfn.RANK.EQ(C1031,$C$2:$C$1031) -> 734 | E1031: =Sheet1!C1031+Sheet1!D1031+Sheet1!E1031+Sheet1!F1031+Sheet1!J1031+Sheet1!K1031+Sheet1!L1031+Sheet1!M1031+Sheet1!Q1031+Sheet1!R1031+Sheet1!S1031+Sheet1!T1031 -> 1539.2 | F1031: =IF(ISNUMBER(E1031),E1031,"") -> 1539.2 | G1031: =_xlfn.RANK.EQ(F1031,$F$2:$F$1031) -> 689 | H1031: =INDEX(Sheet1!AD:AD,MATCH(Sheet1!A1031,Sheet3!A:A,0)) -> 689

Sheet Sheet2
A1: ID | B1: FIRST YEAR RANK | C1: SECOND YEAR RANK C | D1: THIRD YEAR RANK C | E1: FOURTH YEAR RANK C
A2: 4 | B2: =INDEX(Sheet1!I:I,MATCH(Sheet1!A2,Sheet2!A:A,0)) -> 394 | C2: =INDEX(Sheet3!D:D,MATCH(Sheet2!A2,Sheet3!A:A,0)) -> 437 | D2: =INDEX(Sheet3!G:G,MATCH(Sheet2!A2,Sheet3!A:A,0)) -> 430 | E2: =INDEX(Sheet3!H:H,MATCH(Sheet2!A2,Sheet3!A:A,0)) -> 430
A3: 6 | B3: =INDEX(Sheet1!I:I,MATCH(Sheet1!A3,Sheet2!A:A,0)) -> 385 | C3: =INDEX(Sheet3!D:D,MATCH(Sheet2!A3,Sheet3!A:A,0)) -> 545 | D3: =INDEX(Sheet3!G:G,MATCH(Sheet2!A3,Sheet3!A:A,0)) -> 590 | E3: =INDEX(Sheet3!H:H,MATCH(Sheet2!A3,Sheet3!A:A,0)) -> 590
A4: 9 | B4: =INDEX(Sheet1!I:I,MATCH(Sheet1!A4,Sheet2!A:A,0)) -> 24 | C4: =INDEX(Sheet3!D:D,MATCH(Sheet2!A4,Sheet3!A:A,0)) -> 40 | D4: =INDEX(Sheet3!G:G,MATCH(Sheet2!A4,Sheet3!A:A,0)) -> 35 | E4: =INDEX(Sheet3!H:H,MATCH(Sheet2!A4,Sheet3!A:A,0)) -> 35
A5: 13 | B5: =INDEX(Sheet1!I:I,MATCH(Sheet1!A5,Sheet2!A:A,0)) -> 969 | C5: =INDEX(Sheet3!D:D,MATCH(Sheet2!A5,Sheet3!A:A,0)) -> 998 | D5: =INDEX(Sheet3!G:G,MATCH(Sheet2!A5,Sheet3!A:A,0)) -> 972 | E5: =INDEX(Sheet3!H:H,MATCH(Sheet2!A5,Sheet3!A:A,0)) -> 972
A6: 15 | B6: =INDEX(Sheet1!I:I,MATCH(Sheet1!A6,Sheet2!A:A,0)) -> 590 | C6: =INDEX(Sheet3!D:D,MATCH(Sheet2!A6,Sheet3!A:A,0)) -> 459 | D6: =INDEX(Sheet3!G:G,MATCH(Sheet2!A6,Sheet3!A:A,0)) -> 466 | E6: =INDEX(Sheet3!H:H,MATCH(Sheet2!A6,Sheet3!A:A,0)) -> 466
A7: 31 | B7: =INDEX(Sheet1!I:I,MATCH(Sheet1!A7,Sheet2!A:A,0)) -> 245 | C7: =INDEX(Sheet3!D:D,MATCH(Sheet2!A7,Sheet3!A:A,0)) -> 184 | D7: =INDEX(Sheet3!G:G,MATCH(Sheet2!A7,Sheet3!A:A,0)) -> 170 | E7: =INDEX(Sheet3!H:H,MATCH(Sheet2!A7,Sheet3!A:A,0)) -> 170
A8: 32 | B8: =INDEX(Sheet1!I:I,MATCH(Sheet1!A8,Sheet2!A:A,0)) -> 370 | C8: =INDEX(Sheet3!D:D,MATCH(Sheet2!A8,Sheet3!A:A,0)) -> 370 | D8: =INDEX(Sheet3!G:G,MATCH(Sheet2!A8,Sheet3!A:A,0)) -> 315 | E8: =INDEX(Sheet3!H:H,MATCH(Sheet2!A8,Sheet3!A:A,0)) -> 315
A9: 34 | B9: =INDEX(Sheet1!I:I,MATCH(Sheet1!A9,Sheet2!A:A,0)) -> 858 | C9: =INDEX(Sheet3!D:D,MATCH(Sheet2!A9,Sheet3!A:A,0)) -> 759 | D9: =INDEX(Sheet3!G:G,MATCH(Sheet2!A9,Sheet3!A:A,0)) -> 764 | E9: =INDEX(Sheet3!H:H,MATCH(Sheet2!A9,Sheet3!A:A,0)) -> 764
A10: 35 | B10: =INDEX(Sheet1!I:I,MATCH(Sheet1!A10,Sheet2!A:A,0)) -> 759 | C10: =INDEX(Sheet3!D:D,MATCH(Sheet2!A10,Sheet3!A:A,0)) -> 699 | D10: =INDEX(Sheet3!G:G,MATCH(Sheet2!A10,Sheet3!A:A,0)) -> 634 | E10: =INDEX(Sheet3!H:H,MATCH(Sheet2!A10,Sheet3!A:A,0)) -> 634
A11: 37 | B11: =INDEX(Sheet1!I:I,MATCH(Sheet1!A11,Sheet2!A:A,0)) -> 8 | C11: =INDEX(Sheet3!D:D,MATCH(Sheet2!A11,Sheet3!A:A,0)) -> 27 | D11: =INDEX(Sheet3!G:G,MATCH(Sheet2!A11,Sheet3!A:A,0)) -> 41 | E11: =INDEX(Sheet3!H:H,MATCH(Sheet2!A11,Sheet3!A:A,0)) -> 41
A12: 38 | B12: =INDEX(Sheet1!I:I,MATCH(Sheet1!A12,Sheet2!A:A,0)) -> 895 | C12: =INDEX(Sheet3!D:D,MATCH(Sheet2!A12,Sheet3!A:A,0)) -> 872 | D12: =INDEX(Sheet3!G:G,MATCH(Sheet2!A12,Sheet3!A:A,0)) -> 842 | E12: =INDEX(Sheet3!H:H,MATCH(Sheet2!A12,Sheet3!A:A,0)) -> 842
A13: 39 | B13: =INDEX(Sheet1!I:I,MATCH(Sheet1!A13,Sheet2!A:A,0)) -> 107 | C13: =INDEX(Sheet3!D:D,MATCH(Sheet2!A13,Sheet3!A:A,0)) -> 108 | D13: =INDEX(Sheet3!G:G,MATCH(Sheet2!A13,Sheet3!A:A,0)) -> 105 | E13: =INDEX(Sheet3!H:H,MATCH(Sheet2!A13,Sheet3!A:A,0)) -> 105
... A1031: 2603 | B1031: =INDEX(Sheet1!I:I,MATCH(Sheet1!A1031,Sheet2!A:A,0)) -> 868 | C1031: =INDEX(Sheet3!D:D,MATCH(Sheet2!A1031,Sheet3!A:A,0)) -> 734 | D1031: =INDEX(Sheet3!G:G,MATCH(Sheet2!A1031,Sheet3!A:A,0)) -> 689 | E1031: =INDEX(Sheet3!H:H,MATCH(Sheet2!A1031,Sheet3!A:A,0)) -> 689
B1032: =INDEX(Sheet1!I:I,MATCH(Sheet1!A1032,Sheet2!A:A,0)) -> #N/A | C1032: =INDEX(Sheet3!D:D,MATCH(Sheet2!A1032,Sheet3!A:A,0)) -> #N/A | D1032: =INDEX(Sheet3!G:G,MATCH(Sheet2!A1032,Sheet3!A:A,0)) -> #N/A | E1032: =INDEX(Sheet3!H:H,MATCH(Sheet2!A1032,Sheet3!A:A,0)) -> #N/A
B1033: =INDEX(Sheet1!I:I,MATCH(Sheet1!A1033,Sheet2!A:A,0)) -> #N/A | C1033: =INDEX(Sheet3!D:D,MATCH(Sheet2!A1033,Sheet3!A:A,0)) -> #N/A | D1033: =INDEX(Sheet3!G:G,MATCH(Sheet2!A1033,Sheet3!A:A,0)) -> #N/A | E1033: =INDEX(Sheet3!H:H,MATCH(Sheet2!A1033,Sheet3!A:A,0)) -> #N/A
B1034: =INDEX(Sheet1!I:I,MATCH(Sheet1!A1034,Sheet2!A:A,0)) -> #N/A | C1034: =INDEX(Sheet3!D:D,MATCH(Sheet2!A1034,Sheet3!A:A,0)) -> #N/A | D1034: =INDEX(Sheet3!G:G,MATCH(Sheet2!A1034,Sheet3!A:A,0)) -> #N/A | E1034: =INDEX(Sheet3!H:H,MATCH(Sheet2!A1034,Sheet3!A:A,0)) -> #N/A
B1035: =INDEX(Sheet1!I:I,MATCH(Sheet1!A1035,Sheet2!A:A,0)) -> #N/A | C1035: =INDEX(Sheet3!D:D,MATCH(Sheet2!A1035,Sheet3!A:A,0)) -> #N/A | D1035: =INDEX(Sheet3!G:G,MATCH(Sheet2!A1035,Sheet3!A:A,0)) -> #N/A | E1035: =INDEX(Sheet3!H:H,MATCH(Sheet2!A1035,Sheet3!A:A,0)) -> #N/A
B1036: =INDEX(Sheet1!I:I,MATCH(Sheet1!A1036,Sheet2!A:A,0)) -> #N/A | C1036: =INDEX(Sheet3!D:D,MATCH(Sheet2!A1036,Sheet3!A:A,0)) -> #N/A | D1036: =INDEX(Sheet3!G:G,MATCH(Sheet2!A1036,Sheet3!A:A,0)) -> #N/A | E1036: =INDEX(Sheet3!H:H,MATCH(Sheet2!A1036,Sheet3!A:A,0)) -> #N/A
B1037: =INDEX(Sheet1!I:I,MATCH(Sheet1!A1037,Sheet2!A:A,0)) -> #N/A | C1037: =INDEX(Sheet3!D:D,MATCH(Sheet2!A1037,Sheet3!A:A,0)) -> #N/A | D1037: =INDEX(Sheet3!G:G,MATCH(Sheet2!A1037,Sheet3!A:A,0)) -> #N/A | E1037: =INDEX(Sheet3!H:H,MATCH(Sheet2!A1037,Sheet3!A:A,0)) -> #N/A
B1038: =INDEX(Sheet1!I:I,MATCH(Sheet1!A1038,Sheet2!A:A,0)) -> #N/A | C1038: =INDEX(Sheet3!D:D,MATCH(Sheet2!A1038,Sheet3!A:A,0)) -> #N/A | D1038: =INDEX(Sheet3!G:G,MATCH(Sheet2!A1038,Sheet3!A:A,0)) -> #N/A | E1038: =INDEX(Sheet3!H:H,MATCH(Sheet2!A1038,Sheet3!A:A,0)) -> #N/A
B1039: =INDEX(Sheet1!I:I,MATCH(Sheet1!A1039,Sheet2!A:A,0)) -> #N/A | C1039: =INDEX(Sheet3!D:D,MATCH(Sheet2!A1039,Sheet3!A:A,0)) -> #N/A | D1039: =INDEX(Sheet3!G:G,MATCH(Sheet2!A1039,Sheet3!A:A,0)) -> #N/A | E1039: =INDEX(Sheet3!H:H,MATCH(Sheet2!A1039,Sheet3!A:A,0)) -> #N/A
B1040: =INDEX(Sheet1!I:I,MATCH(Sheet1!A1040,Sheet2!A:A,0)) -> #N/A | C1040: =INDEX(Sheet3!D:D,MATCH(Sheet2!A1040,Sheet3!A:A,0)) -> #N/A | D1040: =INDEX(Sheet3!G:G,MATCH(Sheet2!A1040,Sheet3!A:A,0)) -> #N/A | E1040: =INDEX(Sheet3!H:H,MATCH(Sheet2!A1040,Sheet3!A:A,0)) -> #N/A
B1041: =INDEX(Sheet1!I:I,MATCH(Sheet1!A1041,Sheet2!A:A,0)) -> #N/A | C1041: =INDEX(Sheet3!D:D,MATCH(Sheet2!A1041,Sheet3!A:A,0)) -> #N/A | D1041: =INDEX(Sheet3!G:G,MATCH(Sheet2!A1041,Sheet3!A:A,0)) -> #N/A | E1041: =INDEX(Sheet3!H:H,MATCH(Sheet2!A1041,Sheet3!A:A,0)) -> #N/A
B1042: =INDEX(Sheet1!I:I,MATCH(Sheet1!A1042,Sheet2!A:A,0)) -> #N/A | C1042: =INDEX(Sheet3!D:D,MATCH(Sheet2!A1042,Sheet3!A:A,0)) -> #N/A | D1042: =INDEX(Sheet3!G:G,MATCH(Sheet2!A1042,Sheet3!A:A,0)) -> #N/A | E1042: =INDEX(Sheet3!H:H,MATCH(Sheet2!A1042,Sheet3!A:A,0)) -> #N/A
B1043: =INDEX(Sheet1!I:I,MATCH(Sheet1!A1043,Sheet2!A:A,0)) -> #N/A | C1043: =INDEX(Sheet3!D:D,MATCH(Sheet2!A1043,Sheet3!A:A,0)) -> #N/A | D1043: =INDEX(Sheet3!G:G,MATCH(Sheet2!A1043,Sheet3!A:A,0)) -> #N/A | E1043: =INDEX(Sheet3!H:H,MATCH(Sheet2!A1043,Sheet3!A:A,0)) -> #N/A
... B1082: =INDEX(Sheet1!I:I,MATCH(Sheet1!A1082,Sheet2!A:A,0)) -> #N/A | C1082: =INDEX(Sheet3!D:D,MATCH(Sheet2!A1082,Sheet3!A:A,0)) -> #N/A | D1082: =INDEX(Sheet3!G:G,MATCH(Sheet2!A1082,Sheet3!A:A,0)) -> #N/A | E1082: =INDEX(Sheet3!H:H,MATCH(Sheet2!A1082,Sheet3!A:A,0)) -> #N/A
B1083: =INDEX(Sheet1!I:I,MATCH(Sheet1!A1084,Sheet2!A:A,0)) -> #N/A | C1083: =INDEX(Sheet3!D:D,MATCH(Sheet2!A1083,Sheet3!A:A,0)) -> #N/A | D1083: =INDEX(Sheet3!G:G,MATCH(Sheet2!A1083,Sheet3!A:A,0)) -> #N/A | E1083: =INDEX(Sheet3!H:H,MATCH(Sheet2!A1083,Sheet3!A:A,0)) -> #N/A
B1084: =INDEX(Sheet1!I:I,MATCH(Sheet1!A1085,Sheet2!A:A,0)) -> #N/A | C1084: =INDEX(Sheet3!D:D,MATCH(Sheet2!A1084,Sheet3!A:A,0)) -> #N/A | D1084: =INDEX(Sheet3!G:G,MATCH(Sheet2!A1084,Sheet3!A:A,0)) -> #N/A | E1084: =INDEX(Sheet3!H:H,MATCH(Sheet2!A1084,Sheet3!A:A,0)) -> #N/A
B1085: =INDEX(Sheet1!I:I,MATCH(Sheet1!A1086,Sheet2!A:A,0)) -> #N/A | C1085: =INDEX(Sheet3!D:D,MATCH(Sheet2!A1085,Sheet3!A:A,0)) -> #N/A | D1085: =INDEX(Sheet3!G:G,MATCH(Sheet2!A1085,Sheet3!A:A,0)) -> #N/A | E1085: =INDEX(Sheet3!H:H,MATCH(Sheet2!A1085,Sheet3!A:A,0)) -> #N/A
B1086: =INDEX(Sheet1!I:I,MATCH(Sheet1!A1087,Sheet2!A:A,0)) -> #N/A | C1086: =INDEX(Sheet3!D:D,MATCH(Sheet2!A1086,Sheet3!A:A,0)) -> #N/A | D1086: =INDEX(Sheet3!G:G,MATCH(Sheet2!A1086,Sheet3!A:A,0)) -> #N/A | E1086: =INDEX(Sheet3!H:H,MATCH(Sheet2!A1086,Sheet3!A:A,0)) -> #N/A
B1087: =INDEX(Sheet1!I:I,MATCH(Sheet1!A1088,Sheet2!A:A,0)) -> #N/A | C1087: =INDEX(Sheet3!D:D,MATCH(Sheet2!A1087,Sheet3!A:A,0)) -> #N/A | D1087: =INDEX(Sheet3!G:G,MATCH(Sheet2!A1087,Sheet3!A:A,0)) -> #N/A | E1087: =INDEX(Sheet3!H:H,MATCH(Sheet2!A1087,Sheet3!A:A,0)) -> #N/A
B1088: =INDEX(Sheet1!I:I,MATCH(Sheet1!A1089,Sheet2!A:A,0)) -> #N/A | C1088: =INDEX(Sheet3!D:D,MATCH(Sheet2!A1088,Sheet3!A:A,0)) -> #N/A | D1088: =INDEX(Sheet3!G:G,MATCH(Sheet2!A1088,Sheet3!A:A,0)) -> #N/A | E1088: =INDEX(Sheet3!H:H,MATCH(Sheet2!A1088,Sheet3!A:A,0)) -> #N/A
B1089: =INDEX(Sheet1!I:I,MATCH(Sheet1!A1090,Sheet2!A:A,0)) -> #N/A | C1089: =INDEX(Sheet3!D:D,MATCH(Sheet2!A1089,Sheet3!A:A,0)) -> #N/A | D1089: =INDEX(Sheet3!G:G,MATCH(Sheet2!A1089,Sheet3!A:A,0)) -> #N/A | E1089: =INDEX(Sheet3!H:H,MATCH(Sheet2!A1089,Sheet3!A:A,0)) -> #N/A
B1090: =INDEX(Sheet1!I:I,MATCH(Sheet1!A1091,Sheet2!A:A,0)) -> #N/A | C1090: =INDEX(Sheet3!D:D,MATCH(Sheet2!A1090,Sheet3!A:A,0)) -> #N/A | D1090: =INDEX(Sheet3!G:G,MATCH(Sheet2!A1090,Sheet3!A:A,0)) -> #N/A | E1090: =INDEX(Sheet3!H:H,MATCH(Sheet2!A1090,Sheet3!A:A,0)) -> #N/A
B1091: =INDEX(Sheet1!I:I,MATCH(Sheet1!A1092,Sheet2!A:A,0)) -> #N/A | C1091: =INDEX(Sheet3!D:D,MATCH(Sheet2!A1091,Sheet3!A:A,0)) -> #N/A | D1091: =INDEX(Sheet3!G:G,MATCH(Sheet2!A1091,Sheet3!A:A,0)) -> #N/A | E1091: =INDEX(Sheet3!H:H,MATCH(Sheet2!A1091,Sheet3!A:A,0)) -> #N/A
B1092: =INDEX(Sheet1!I:I,MATCH(Sheet1!A1093,Sheet2!A:A,0)) -> #N/A | C1092: =INDEX(Sheet3!D:D,MATCH(Sheet2!A1092,Sheet3!A:A,0)) -> #N/A | D1092: =INDEX(Sheet3!G:G,MATCH(Sheet2!A1092,Sheet3!A:A,0)) -> #N/A | E1092: =INDEX(Sheet3!H:H,MATCH(Sheet2!A1092,Sheet3!A:A,0)) -> #N/A
B1093: =INDEX(Sheet1!I:I,MATCH(Sheet1!A1094,Sheet2!A:A,0)) -> #N/A | C1093: =INDEX(Sheet3!D:D,MATCH(Sheet2!A1093,Sheet3!A:A,0)) -> #N/A | D1093: =INDEX(Sheet3!G:G,MATCH(Sheet2!A1093,Sheet3!A:A,0)) -> #N/A | E1093: =INDEX(Sheet3!H:H,MATCH(Sheet2!A1093,Sheet3!A:A,0)) -> #N/A
B1094: =INDEX(Sheet1!I:I,MATCH(Sheet1!A1095,Sheet2!A:A,0)) -> #N/A | C1094: =INDEX(Sheet3!D:D,MATCH(Sheet2!A1094,Sheet3!A:A,0)) -> #N/A | D1094: =INDEX(Sheet3!G:G,MATCH(Sheet2!A1094,Sheet3!A:A,0)) -> #N/A | E1094: =INDEX(Sheet3!H:H,MATCH(Sheet2!A1094,Sheet3!A:A,0)) -> #N/A
... B1115: =INDEX(Sheet1!I:I,MATCH(Sheet1!A1116,Sheet2!A:A,0)) -> #N/A | C1115: =INDEX(Sheet3!D:D,MATCH(Sheet2!A1115,Sheet3!A:A,0)) -> #N/A | D1115: =INDEX(Sheet3!G:G,MATCH(Sheet2!A1115,Sheet3!A:A,0)) -> #N/A | E1115: =INDEX(Sheet3!H:H,MATCH(Sheet2!A1115,Sheet3!A:A,0)) -> #N/A

Sheet Sheet1
A1: ID | B1: NAME | C1: FIRST YEAR | D1: PROFESSIONALISM STEP I | E1: RESEARCH STEP I | F1: COMMUNICATION STEP I | I1: FIRST YEAR RANK | J1: SECOND YEAR | K1: RESEARCH STEP II | L1: PROFESSIONALISM STEP II | M1: COMMUNICATION STEP II | P1: SECOND YEAR RANK | Q1: THIRD YEAR | R1: RESEARCH STEP III | S1: COMMUNICATION STEP III | T1: PROFESSIONALISM STEP III | W1: THIRD YEAR RANK | X1: FOURTH YEAR | Z1: FOURTH YEAR RANK | AA1: PERCENTAGE | AB1: TOTAL | AD1: TOTAL RANK
A2: 4 | B2: ابرار عدلى ابراهيم على بيبرس | C2: 596.9 | D2: 23 | E2: 23 | F2: 22 | G2: =C2+D2+E2+F2 -> 664.9 | H2: =IF(ISNUMBER(G2),G2,"") -> 664.9 | I2: =_xlfn.RANK.EQ(H2,$H$2:$H$1116) -> 394 | J2: 577 | K2: 47 | L2: 22 | M2: 21 | N2: =J2+K2+L2+M2 -> 667 | O2: =IF(ISNUMBER(N2),N2,"") -> 667 | P2: =_xlfn.RANK.EQ(O2,$O$2:$O$1116) -> 492 | Q2: 252.5 | R2: 46.5 | S2: 21 | T2: 23 | U2: =Q2+R2+S2+T2 -> 343 | V2: =IF(ISNUMBER(U2),U2,"") -> 343 | W2: =_xlfn.RANK.EQ(V2,$V$2:$V$1116) -> 456 | Y2: =IF(ISNUMBER(X2),X2,"") | Z2: =_xlfn.RANK.EQ(Y2,$Y$2:$Y$1116) -> #VALUE! | AA2: =AB2/3180 -> 0.52669811 | AB2: =C2+D2+E2+F2+J2+K2+L2+M2+Q2+R2+S2+T2+X2 -> 1674.9 | AC2: =IF(ISNUMBER(AB2),AB2,"") -> 1674.9 | AD2: =_xlfn.RANK.EQ(AC2,$AC$2:$AC$1116) -> 430
A3: 6 | B3: ابراهيم احمد جابر سلام | C3: 601.8 | D3: 23 | E3: 21 | F3: 20 | G3: =C3+D3+E3+F3 -> 665.8 | H3: =IF(ISNUMBER(G3),G3,"") -> 665.8 | I3: =_xlfn.RANK.EQ(H3,$H$2:$H$1116) -> 385 | J3: 552.7 | K3: 37 | L3: 21 | M3: 15 | N3: =J3+K3+L3+M3 -> 625.7 | O3: =IF(ISNUMBER(N3),N3,"") -> 625.7 | P3: =_xlfn.RANK.EQ(O3,$O$2:$O$1116) -> 719 | Q3: 219.5 | R3: 42.5 | S3: 21 | T3: 24 | U3: =Q3+R3+S3+T3 -> 307 | V3: =IF(ISNUMBER(U3),U3,"") -> 307 | W3: =_xlfn.RANK.EQ(V3,$V$2:$V$1116) -> 756 | Y3: =IF(ISNUMBER(X3),X3,"") | Z3: =_xlfn.RANK.EQ(Y3,$Y$2:$Y$1116) -> #VALUE! | AA3: =AB3/3180 -> 0.50267296 | AB3: =C3+D3+E3+F3+J3+K3+L3+M3+Q3+R3+S3+T3+X3 -> 1598.5 | AC3: =IF(ISNUMBER(AB3),AB3,"") -> 1598.5 | AD3: =_xlfn.RANK.EQ(AC3,$AC$2:$AC$1116) -> 590
A4: 9 | B4: ابراهيم حسنى محمد على حسونه | C4: 654 | D4: 25 | E4: 25 | F4: 23 | G4: =C4+D4+E4+F4 -> 727 | H4: =IF(ISNUMBER(G4),G4,"") -> 727 | I4: =_xlfn.RANK.EQ(H4,$H$2:$H$1116) -> 24 | J4: 635.5 | K4: 48 | L4: 19 | M4: 23 | N4: =J4+K4+L4+M4 -> 725.5 | O4: =IF(ISNUMBER(N4),N4,"") -> 725.5 | P4: =_xlfn.RANK.EQ(O4,$O$2:$O$1116) -> 82 | Q4: 289 | R4: 48.5 | S4: 23 | T4: 25 | U4: =Q4+R4+S4+T4 -> 385.5 | V4: =IF(ISNUMBER(U4),U4,"") -> 385.5 | W4: =_xlfn.RANK.EQ(V4,$V$2:$V$1116) -> 32 | Y4: =IF(ISNUMBER(X4),X4,"") | Z4: =_xlfn.RANK.EQ(Y4,$Y$2:$Y$1116) -> #VALUE! | AA4: =AB4/3180 -> 0.57798742 | AB4: =C4+D4+E4+F4+J4+K4+L4+M4+Q4+R4+S4+T4+X4 -> 1838 | AC4: =IF(ISNUMBER(AB4),AB4,"") -> 1838 | AD4: =_xlfn.RANK.EQ(AC4,$AC$2:$AC$1116) -> 35
A5: 13 | B5: ابراهيم علاء مرزوق على اغا | C5: 440 | D5: 23 | E5: 6 | F5: 18 | G5: =C5+D5+E5+F5 -> 487 | H5: =IF(ISNUMBER(G5),G5,"") -> 487 | I5: =_xlfn.RANK.EQ(H5,$H$2:$H$1116) -> 969 | J5: 407.5 | K5: 23 | L5: 13 | M5: 11 | N5: =J5+K5+L5+M5 -> 454.5 | O5: =IF(ISNUMBER(N5),N5,"") -> 454.5 | P5: =_xlfn.RANK.EQ(O5,$O$2:$O$1116) -> 1022 | Q5: 152.75 | R5: 34 | S5: 22 | T5: 22 | U5: =Q5+R5+S5+T5 -> 230.75 | V5: =IF(ISNUMBER(U5),U5,"") -> 230.75 | W5: =_xlfn.RANK.EQ(V5,$V$2:$V$1116) -> 974 | Y5: =IF(ISNUMBER(X5),X5,"") | Z5: =_xlfn.RANK.EQ(Y5,$Y$2:$Y$1116) -> #VALUE! | AA5: =AB5/3180 -> 0.36863208 | AB5: =C5+D5+E5+F5+J5+K5+L5+M5+Q5+R5+S5+T5+X5 -> 1172.25 | AC5: =IF(ISNUMBER(AB5),AB5,"") -> 1172.25 | AD5: =_xlfn.RANK.EQ(AC5,$AC$2:$AC$1116) -> 972
A6: 15 | B6: ابراهيم محمد حسن عويضه | C6: 565.6 | D6: 24 | E6: 22 | F6: 18 | G6: =C6+D6+E6+F6 -> 629.6 | H6: =IF(ISNUMBER(G6),G6,"") -> 629.6 | I6: =_xlfn.RANK.EQ(H6,$H$2:$H$1116) -> 590 | J6: 599.5 | K6: 49 | L6: 25 | M6: 22 | N6: =J6+K6+L6+M6 -> 695.5 | O6: =IF(ISNUMBER(N6),N6,"") -> 695.5 | P6: =_xlfn.RANK.EQ(O6,$O$2:$O$1116) -> 316 | Q6: 243 | R6: 43 | S6: 22 | T6: 25 | U6: =Q6+R6+S6+T6 -> 333 | V6: =IF(ISNUMBER(U6),U6,"") -> 333 | W6: =_xlfn.RANK.EQ(V6,$V$2:$V$1116) -> 542 | Y6: =IF(ISNUMBER(X6),X6,"") | Z6: =_xlfn.RANK.EQ(Y6,$Y$2:$Y$1116) -> #VALUE! | AA6: =AB6/3180 -> 0.52141509 | AB6: =C6+D6+E6+F6+J6+K6+L6+M6+Q6+R6+S6+T6+X6 -> 1658.1 | AC6: =IF(ISNUMBER(AB6),AB6,"") -> 1658.1 | AD6: =_xlfn.RANK.EQ(AC6,$AC$2:$AC$1116) -> 466
A7: 31 | B7: احلام محمد خميس على عبدالكريم | C7: 616.7 | D7: 25 | E7: 24 | F7: 23 | G7: =C7+D7+E7+F7 -> 688.7 | H7: =IF(ISNUMBER(G7),G7,"") -> 688.7 | I7: =_xlfn.RANK.EQ(H7,$H$2:$H$1116) -> 245 | J7: 629.4 | K7: 46 | L7: 21 | M7: 22 | N7: =J7+K7+L7+M7 -> 718.4 | O7: =IF(ISNUMBER(N7),N7,"") -> 718.4 | P7: =_xlfn.RANK.EQ(O7,$O$2:$O$1116) -> 129 | Q7: 272 | R7: 48 | S7: 24 | T7: 25 | U7: =Q7+R7+S7+T7 -> 369 | V7: =IF(ISNUMBER(U7),U7,"") -> 369 | W7: =_xlfn.RANK.EQ(V7,$V$2:$V$1116) -> 163 | Y7: =IF(ISNUMBER(X7),X7,"") | Z7: =_xlfn.RANK.EQ(Y7,$Y$2:$Y$1116) -> #VALUE! | AA7: =AB7/3180 -> 0.55852201 | AB7: =C7+D7+E7+F7+J7+K7+L7+M7+Q7+R7+S7+T7+X7 -> 1776.1 | AC7: =IF(ISNUMBER(AB7),AB7,"") -> 1776.1 | AD7: =_xlfn.RANK.EQ(AC7,$AC$2:$AC$1116) -> 170
A8: 32 | B8: احمد ابراهيم ابراهيم سيد احمد عيسى | C8: 598.8 | D8: 24 | E8: 22 | F8: 24 | G8: =C8+D8+E8+F8 -> 668.8 | H8: =IF(ISNUMBER(G8),G8,"") -> 668.8 | I8: =_xlfn.RANK.EQ(H8,$H$2:$H$1116) -> 370 | J8: 589.8 | K8: 49 | L8: 22 | M8: 25 | N8: =J8+K8+L8+M8 -> 685.8 | O8: =IF(ISNUMBER(N8),N8,"") -> 685.8 | P8: =_xlfn.RANK.EQ(O8,$O$2:$O$1116) -> 385 | Q8: 272 | R8: 47.5 | S8: 24 | T8: 25 | U8: =Q8+R8+S8+T8 -> 368.5 | V8: =IF(ISNUMBER(U8),U8,"") -> 368.5 | W8: =_xlfn.RANK.EQ(V8,$V$2:$V$1116) -> 170 | Y8: =IF(ISNUMBER(X8),X8,"") | Z8: =_xlfn.RANK.EQ(Y8,$Y$2:$Y$1116) -> #VALUE! | AA8: =AB8/3180 -> 0.54185535 | AB8: =C8+D8+E8+F8+J8+K8+L8+M8+Q8+R8+S8+T8+X8 -> 1723.1 | AC8: =IF(ISNUMBER(AB8),AB8,"") -> 1723.1 | AD8: =_xlfn.RANK.EQ(AC8,$AC$2:$AC$1116) -> 315
A9: 34 | B9: احمد ابراهيم فاروق سعد الششتاوى | C9: 477 | D9: 24 | E9: 22 | F9: 24 | G9: =C9+D9+E9+F9 -> 547 | H9: =IF(ISNUMBER(G9),G9,"") -> 547 | I9: =_xlfn.RANK.EQ(H9,$H$2:$H$1116) -> 858 | J9: 545.3 | K9: 49 | L9: 22 | M9: 23 | N9: =J9+K9+L9+M9 -> 639.3 | O9: =IF(ISNUMBER(N9),N9,"") -> 639.3 | P9: =_xlfn.RANK.EQ(O9,$O$2:$O$1116) -> 654 | Q9: 226.5 | R9: 31.5 | S9: 16 | T9: 23 | U9: =Q9+R9+S9+T9 -> 297 | V9: =IF(ISNUMBER(U9),U9,"") -> 297 | W9: =_xlfn.RANK.EQ(V9,$V$2:$V$1116) -> 809 | Y9: =IF(ISNUMBER(X9),X9,"") | Z9: =_xlfn.RANK.EQ(Y9,$Y$2:$Y$1116) -> #VALUE! | AA9: =AB9/3180 -> 0.46644654 | AB9: =C9+D9+E9+F9+J9+K9+L9+M9+Q9+R9+S9+T9+X9 -> 1483.3 | AC9: =IF(ISNUMBER(AB9),AB9,"") -> 1483.3 | AD9: =_xlfn.RANK.EQ(AC9,$AC$2:$AC$1116) -> 764
A10: 35 | B10: احمد احمد ابراهيم احمد عويضه | C10: 515.2 | D10: 21 | E10: 25 | F10: 20.5 | G10: =C10+D10+E10+F10 -> 581.7 | H10: =IF(ISNUMBER(G10),G10,"") -> 581.7 | I10: =_xlfn.RANK.EQ(H10,$H$2:$H$1116) -> 759 | J10: 551 | K10: 46 | L10: 22 | M10: 23 | N10: =J10+K10+L10+M10 -> 642 | O10: =IF(ISNUMBER(N10),N10,"") -> 642 | P10: =_xlfn.RANK.EQ(O10,$O$2:$O$1116) -> 634 | Q10: 264 | R10: 45 | S10: 22 | T10: 23.5 | U10: =Q10+R10+S10+T10 -> 354.5 | V10: =IF(ISNUMBER(U10),U10,"") -> 354.5 | W10: =_xlfn.RANK.EQ(V10,$V$2:$V$1116) -> 317 | Y10: =IF(ISNUMBER(X10),X10,"") | Z10: =_xlfn.RANK.EQ(Y10,$Y$2:$Y$1116) -> #VALUE! | AA10: =AB10/3180 -> 0.49628931 | AB10: =C10+D10+E10+F10+J10+K10+L10+M10+Q10+R10+S10+T10+X10 -> 1578.2 | AC10: =IF(ISNUMBER(AB10),AB10,"") -> 1578.2 | AD10: =_xlfn.RANK.EQ(AC10,$AC$2:$AC$1116) -> 634
A11: 37 | B11: احمد اشرف عبد الزين عباس | C11: 658 | D11: 25 | E11: 25 | F11: 24 | G11: =C11+D11+E11+F11 -> 732 | H11: =IF(ISNUMBER(G11),G11,"") -> 732 | I11: =_xlfn.RANK.EQ(H11,$H$2:$H$1116) -> 8 | J11: 633.7 | K11: 47 | L11: 23 | M11: 23 | N11: =J11+K11+L11+M11 -> 726.7 | O11: =IF(ISNUMBER(N11),N11,"") -> 726.7 | P11: =_xlfn.RANK.EQ(O11,$O$2:$O$1116) -> 75 | Q11: 283 | R11: 47 | S11: 22 | T11: 24.5 | U11: =Q11+R11+S11+T11 -> 376.5 | V11: =IF(ISNUMBER(U11),U11,"") -> 376.5 | W11: =_xlfn.RANK.EQ(V11,$V$2:$V$1116) -> 94 | Y11: =IF(ISNUMBER(X11),X11,"") | Z11: =_xlfn.RANK.EQ(Y11,$Y$2:$Y$1116) -> #VALUE! | AA11: =AB11/3180 -> 0.57710692 | AB11: =C11+D11+E11+F11+J11+K11+L11+M11+Q11+R11+S11+T11+X11 -> 1835.2 | AC11: =IF(ISNUMBER(AB11),AB11,"") -> 1835.2 | AD11: =_xlfn.RANK.EQ(AC11,$AC$2:$AC$1116) -> 41
A12: 38 | B12: احمد اشرف عبد الفتاح عبد ربه | C12: 472.1 | D12: 19 | E12: 20 | F12: 16 | G12: =C12+D12+E12+F12 -> 527.1 | H12: =IF(ISNUMBER(G12),G12,"") -> 527.1 | I12: =_xlfn.RANK.EQ(H12,$H$2:$H$1116) -> 895 | J12: 510.7 | K12: 34 | L12: 20 | M12: 18 | N12: =J12+K12+L12+M12 -> 582.7 | O12: =IF(ISNUMBER(N12),N12,"") -> 582.7 | P12: =_xlfn.RANK.EQ(O12,$O$2:$O$1116) -> 830 | Q12: 212.5 | R12: 43 | S12: 25 | T12: 22.5 | U12: =Q12+R12+S12+T12 -> 303 | V12: =IF(ISNUMBER(U12),U12,"") -> 303 | W12: =_xlfn.RANK.EQ(V12,$V$2:$V$1116) -> 782 | Y12: =IF(ISNUMBER(X12),X12,"") | Z12: =_xlfn.RANK.EQ(Y12,$Y$2:$Y$1116) -> #VALUE! | AA12: =AB12/3180 -> 0.44427673 | AB12: =C12+D12+E12+F12+J12+K12+L12+M12+Q12+R12+S12+T12+X12 -> 1412.8 | AC12: =IF(ISNUMBER(AB12),AB12,"") -> 1412.8 | AD12: =_xlfn.RANK.EQ(AC12,$AC$2:$AC$1116) -> 842
A13: 39 | B13: احمد اشرف عطية محمود القزاز | C13: 639.5 | D13: 25 | E13: 25 | F13: 22 | G13: =C13+D13+E13+F13 -> 711.5 | H13: =IF(ISNUMBER(G13),G13,"") -> 711.5 | I13: =_xlfn.RANK.EQ(H13,$H$2:$H$1116) -> 107 | J13: 622.7 | K13: 49 | L13: 22 | M13: 23 | N13: =J13+K13+L13+M13 -> 716.7 | O13: =IF(ISNUMBER(N13),N13,"") -> 716.7 | P13: =_xlfn.RANK.EQ(O13,$O$2:$O$1116) -> 141 | Q13: 274.5 | R13: 48 | S13: 24 | T13: 24.5 | U13: =Q13+R13+S13+T13 -> 371 | V13: =IF(ISNUMBER(U13),U13,"") -> 371 | W13: =_xlfn.RANK.EQ(V13,$V$2:$V$1116) -> 140 | Y13: =IF(ISNUMBER(X13),X13,"") | Z13: =_xlfn.RANK.EQ(Y13,$Y$2:$Y$1116) -> #VALUE! | AA13: =AB13/3180 -> 0.56578616 | AB13: =C13+D13+E13+F13+J13+K13+L13+M13+Q13+R13+S13+T13+X13 -> 1799.2 | AC13: =IF(ISNUMBER(AB13),AB13,"") -> 1799.2 | AD13: =_xlfn.RANK.EQ(AC13,$AC$2:$AC$1116) -> 105
... A20: 52 | B20: احمد حسام عبد المجيد علي | C20: 555.6 | D20: 24 | E20: 22 | F20: 16.5 | G20: =C20+D20+E20+F20 -> 618.1 | H20: =IF(ISNUMBER(G20),G20,"") -> 618.1 | I20: =_xlfn.RANK.EQ(H20,$H$2:$H$1116) -> 639 | J20: 490.4 | K20: 30 | L20: 16 | M20: 14 | N20: =J20+K20+L20+M20 -> 550.4 | O20: =IF(ISNUMBER(N20),N20,"") -> 550.4 | P20: =_xlfn.RANK.EQ(O20,$O$2:$O$1116) -> 903 | Q20: 206 | R20: 41.5 | S20: 22 | T20: 23.5 | U20: =Q20+R20+S20+T20 -> 293 | V20: =IF(ISNUMBER(U20),U20,"") -> 293 | W20: =_xlfn.RANK.EQ(V20,$V$2:$V$1116) -> 833 | Y20: =IF(ISNUMBER(X20),X20,"") | Z20: =_xlfn.RANK.EQ(Y20,$Y$2:$Y$1116) -> #VALUE! | AA20: =AB20/3180 -> 0.45959119 | AB20: =C20+D20+E20+F20+J20+K20+L20+M20+Q20+R20+S20+T20+X20 -> 1461.5 | AC20: =IF(ISNUMBER(AB20),AB20,"") -> 1461.5 | AD20: =_xlfn.RANK.EQ(AC20,$AC$2:$AC$1116) -> 799
A21: 53 | B21: احمد حسن ابراهيم المهدى هاشم | C21: 457.1 | D21: 21 | E21: 13 | F21: 21 | G21: =C21+D21+E21+F21 -> 512.1 | H21: =IF(ISNUMBER(G21),G21,"") -> 512.1 | I21: =_xlfn.RANK.EQ(H21,$H$2:$H$1116) -> 925 | J21: 457.5 | K21: 37 | L21: 20 | M21: 15 | N21: =J21+K21+L21+M21 -> 529.5 | O21: =IF(ISNUMBER(N21),N21,"") -> 529.5 | P21: =_xlfn.RANK.EQ(O21,$O$2:$O$1116) -> 936 | Q21: راسب | R21: 40 | S21: 23 | T21: 19.5 | U21: =Q21+R21+S21+T21 -> #VALUE! | V21: =IF(ISNUMBER(U21),U21,"") | W21: =_xlfn.RANK.EQ(V21,$V$2:$V$1116) -> #VALUE! | Y21: =IF(ISNUMBER(X21),X21,"") | Z21: =_xlfn.RANK.EQ(Y21,$Y$2:$Y$1116) -> #VALUE! | AA21: =AB21/3180 -> #VALUE! | AB21: =C21+D21+E21+F21+J21+K21+L21+M21+Q21+R21+S21+T21+X21 -> #VALUE! | AC21: =IF(ISNUMBER(AB21),AB21,"") | AD21: =_xlfn.RANK.EQ(AC21,$AC$2:$AC$1116) -> #VALUE!
A22: 54 | B22: احمد حسن أحمد محمد على | C22: 606.2 | D22: 24 | E22: 20 | F22: 22 | G22: =C22+D22+E22+F22 -> 672.2 | H22: =IF(ISNUMBER(G22),G22,"") -> 672.2 | I22: =_xlfn.RANK.EQ(H22,$H$2:$H$1116) -> 347 | J22: 615 | K22: 49 | L22: 22 | M22: 21 | N22: =J22+K22+L22+M22 -> 707 | O22: =IF(ISNUMBER(N22),N22,"") -> 707 | P22: =_xlfn.RANK.EQ(O22,$O$2:$O$1116) -> 226 | Q22: 262 | R22: 47.5 | S22: 25 | T22: 23.5 | U22: =Q22+R22+S22+T22 -> 358 | V22: =IF(ISNUMBER(U22),U22,"") -> 358 | W22: =_xlfn.RANK.EQ(V22,$V$2:$V$1116) -> 284 | Y22: =IF(ISNUMBER(X22),X22,"") | Z22: =_xlfn.RANK.EQ(Y22,$Y$2:$Y$1116) -> #VALUE! | AA22: =AB22/3180 -> 0.54628931 | AB22: =C22+D22+E22+F22+J22+K22+L22+M22+Q22+R22+S22+T22+X22 -> 1737.2 | AC22: =IF(ISNUMBER(AB22),AB22,"") -> 1737.2 | AD22: =_xlfn.RANK.EQ(AC22,$AC$2:$AC$1116) -> 276
A23: 55 | B23: احمد حسين محمد محمد البصال | C23: 642.7 | D23: 25 | E23: 24 | F23: 24 | G23: =C23+D23+E23+F23 -> 715.7 | H23: =IF(ISNUMBER(G23),G23,"") -> 715.7 | I23: =_xlfn.RANK.EQ(H23,$H$2:$H$1116) -> 79 | J23: 636 | K23: 47 | L23: 24 | M23: 23 | N23: =J23+K23+L23+M23 -> 730 | O23: =IF(ISNUMBER(N23),N23,"") -> 730 | P23: =_xlfn.RANK.EQ(O23,$O$2:$O$1116) -> 47 | Q23: 257 | R23: 45.5 | S23: 23 | T23: 25 | U23: =Q23+R23+S23+T23 -> 350.5 | V23: =IF(ISNUMBER(U23),U23,"") -> 350.5 | W23: =_xlfn.RANK.EQ(V23,$V$2:$V$1116) -> 372 | Y23: =IF(ISNUMBER(X23),X23,"") | Z23: =_xlfn.RANK.EQ(Y23,$Y$2:$Y$1116) -> #VALUE! | AA23: =AB23/3180 -> 0.56484277 | AB23: =C23+D23+E23+F23+J23+K23+L23+M23+Q23+R23+S23+T23+X23 -> 1796.2 | AC23: =IF(ISNUMBER(AB23),AB23,"") -> 1796.2 | AD23: =_xlfn.RANK.EQ(AC23,$AC$2:$AC$1116) -> 114
A24: 58 | B24: احمد خالد عبدالنى عبدالجليل | C24: 499.1 | D24: 18 | E24: 22 | F24: 21 | G24: =C24+D24+E24+F24 -> 560.1 | H24: =IF(ISNUMBER(G24),G24,"") -> 560.1 | I24: =_xlfn.RANK.EQ(H24,$H$2:$H$1116) -> 819 | J24: 578.5 | K24: 40 | L24: 24 | M24: 23 | N24: =J24+K24+L24+M24 -> 665.5 | O24: =IF(ISNUMBER(N24),N24,"") -> 665.5 | P24: =_xlfn.RANK.EQ(O24,$O$2:$O$1116) -> 502 | Q24: 245 | R24: 44 | S24: 24 | T24: 24 | U24: =Q24+R24+S24+T24 -> 337 | V24: =IF(ISNUMBER(U24),U24,"") -> 337 | W24: =_xlfn.RANK.EQ(V24,$V$2:$V$1116) -> 508 | Y24: =IF(ISNUMBER(X24),X24,"") | Z24: =_xlfn.RANK.EQ(Y24,$Y$2:$Y$1116) -> #VALUE! | AA24: =AB24/3180 -> 0.49138365 | AB24: =C24+D24+E24+F24+J24+K24+L24+M24+Q24+R24+S24+T24+X24 -> 1562.6 | AC24: =IF(ISNUMBER(AB24),AB24,"") -> 1562.6 | AD24: =_xlfn.RANK.EQ(AC24,$AC$2:$AC$1116) -> 654
A25: 59 | B25: احمد خالد محمد مبروك صقر | C25: 639.7 | D25: 25 | E25: 24 | F25: 23 | G25: =C25+D25+E25+F25 -> 711.7 | H25: =IF(ISNUMBER(G25),G25,"") -> 711.7 | I25: =_xlfn.RANK.EQ(H25,$H$2:$H$1116) -> 102 | J25: 613 | K25: 47 | L25: 24 | M25: 23 | N25: =J25+K25+L25+M25 -> 707 | O25: =IF(ISNUMBER(N25),N25,"") -> 707 | P25: =_xlfn.RANK.EQ(O25,$O$2:$O$1116) -> 226 | Q25: 260 | R25: 47.5 | S25: 24 | T25: 25 | U25: =Q25+R25+S25+T25 -> 356.5 | V25: =IF(ISNUMBER(U25),U25,"") -> 356.5 | W25: =_xlfn.RANK.EQ(V25,$V$2:$V$1116) -> 299 | Y25: =IF(ISNUMBER(X25),X25,"") | Z25: =_xlfn.RANK.EQ(Y25,$Y$2:$Y$1116) -> #VALUE! | AA25: =AB25/3180 -> 0.55823899 | AB25: =C25+D25+E25+F25+J25+K25+L25+M25+Q25+R25+S25+T25+X25 -> 1775.2 | AC25: =IF(ISNUMBER(AB25),AB25,"") -> 1775.2 | AD25: =_xlfn.RANK.EQ(AC25,$AC$2:$AC$1116) -> 174
A26: 60 | B26: احمد خميس الحسيني حماد | C26: 495.7 | D26: 14 | E26: 17 | F26: 16 | G26: =C26+D26+E26+F26 -> 542.7 | H26: =IF(ISNUMBER(G26),G26,"") -> 542.7 | I26: =_xlfn.RANK.EQ(H26,$H$2:$H$1116) -> 870 | J26: 493 | K26: 48 | L26: 20 | M26: 16 | N26: =J26+K26+L26+M26 -> 577 | O26: =IF(ISNUMBER(N26),N26,"") -> 577 | P26: =_xlfn.RANK.EQ(O26,$O$2:$O$1116) -> 841 | Q26: 223 | R26: 46.5 | S26: 25 | T26: 23.5 | U26: =Q26+R26+S26+T26 -> 318 | V26: =IF(ISNUMBER(U26),U26,"") -> 318 | W26: =_xlfn.RANK.EQ(V26,$V$2:$V$1116) -> 671 | Y26: =IF(ISNUMBER(X26),X26,"") | Z26: =_xlfn.RANK.EQ(Y26,$Y$2:$Y$1116) -> #VALUE! | AA26: =AB26/3180 -> 0.45210692 | AB26: =C26+D26+E26+F26+J26+K26+L26+M26+Q26+R26+S26+T26+X26 -> 1437.7 | AC26: =IF(ISNUMBER(AB26),AB26,"") -> 1437.7 | AD26: =_xlfn.RANK.EQ(AC26,$AC$2:$AC$1116) -> 827
A27: 67 | B27: احمد سامح عبد الرحمن حبيب | C27: 611.4 | D27: 24 | E27: 24 | F27: 25 | G27: =C27+D27+E27+F27 -> 684.4 | H27: =IF(ISNUMBER(G27),G27,"") -> 684.4 | I27: =_xlfn.RANK.EQ(H27,$H$2:$H$1116) -> 268 | J27: 611.5 | K27: 49 | L27: 23 | M27: 23 | N27: =J27+K27+L27+M27 -> 706.5 | O27: =IF(ISNUMBER(N27),N27,"") -> 706.5 | P27: =_xlfn.RANK.EQ(O27,$O$2:$O$1116) -> 233 | Q27: 262 | R27: 45.5 | S27: 24 | T27: 24 | U27: =Q27+R27+S27+T27 -> 355.5 | V27: =IF(ISNUMBER(U27),U27,"") -> 355.5 | W27: =_xlfn.RANK.EQ(V27,$V$2:$V$1116) -> 306 | Y27: =IF(ISNUMBER(X27),X27,"") | Z27: =_xlfn.RANK.EQ(Y27,$Y$2:$Y$1116) -> #VALUE! | AA27: =AB27/3180 -> 0.54918239 | AB27: =C27+D27+E27+F27+J27+K27+L27+M27+Q27+R27+S27+T27+X27 -> 1746.4 | AC27: =IF(ISNUMBER(AB27),AB27,"") -> 1746.4 | AD27: =_xlfn.RANK.EQ(AC27,$AC$2:$AC$1116) -> 243
A28: 68 | B28: احمد سامح عرفه حسن القحافى | C28: 529.9 | D28: 24 | E28: 25 | F28: 22 | G28: =C28+D28+E28+F28 -> 600.9 | H28: =IF(ISNUMBER(G28),G28,"") -> 600.9 | I28: =_xlfn.RANK.EQ(H28,$H$2:$H$1116) -> 704 | J28: 540.5 | K28: 49 | L28: 20 | M28: 24 | N28: =J28+K28+L28+M28 -> 633.5 | O28: =IF(ISNUMBER(N28),N28,"") -> 633.5 | P28: =_xlfn.RANK.EQ(O28,$O$2:$O$1116) -> 682 | Q28: 253 | R28: 45 | S28: 25 | T28: 25 | U28: =Q28+R28+S28+T28 -> 348 | V28: =IF(ISNUMBER(U28),U28,"") -> 348 | W28: =_xlfn.RANK.EQ(V28,$V$2:$V$1116) -> 394 | Y28: =IF(ISNUMBER(X28),X28,"") | Z28: =_xlfn.RANK.EQ(Y28,$Y$2:$Y$1116) -> #VALUE! | AA28: =AB28/3180 -> 0.49761006 | AB28: =C28+D28+E28+F28+J28+K28+L28+M28+Q28+R28+S28+T28+X28 -> 1582.4 | AC28: =IF(ISNUMBER(AB28),AB28,"") -> 1582.4 | AD28: =_xlfn.RANK.EQ(AC28,$AC$2:$AC$1116) -> 623
A29: 72 | B29: احمد سمير السيد علي العيسوي | C29: 601.5 | D29: 25 | E29: 25 | F29: 23 | G29: =C29+D29+E29+F29 -> 674.5 | H29: =IF(ISNUMBER(G29),G29,"") -> 674.5 | I29: =_xlfn.RANK.EQ(H29,$H$2:$H$1116) -> 337 | J29: 608.5 | K29: 49 | L29: 22 | M29: 24 | N29: =J29+K29+L29+M29 -> 703.5 | O29: =IF(ISNUMBER(N29),N29,"") -> 703.5 | P29: =_xlfn.RANK.EQ(O29,$O$2:$O$1116) -> 255 | Q29: 272.5 | R29: 48 | S29: 25 | T29: 25 | U29: =Q29+R29+S29+T29 -> 370.5 | V29: =IF(ISNUMBER(U29),U29,"") -> 370.5 | W29: =_xlfn.RANK.EQ(V29,$V$2:$V$1116) -> 145 | Y29: =IF(ISNUMBER(X29),X29,"") | Z29: =_xlfn.RANK.EQ(Y29,$Y$2:$Y$1116) -> #VALUE! | AA29: =AB29/3180 -> 0.54984277 | AB29: =C29+D29+E29+F29+J29+K29+L29+M29+Q29+R29+S29+T29+X29 -> 1748.5 | AC29: =IF(ISNUMBER(AB29),AB29,"") -> 1748.5 | AD29: =_xlfn.RANK.EQ(AC29,$AC$2:$AC$1116) -> 233
A30: 74 | B30: احمد شحاتة عبدالعزيز عبدالقادر | C30: 621.5 | D30: 24 | E30: 22 | F30: 22 | G30: =C30+D30+E30+F30 -> 689.5 | H30: =IF(ISNUMBER(G30),G30,"") -> 689.5 | I30: =_xlfn.RANK.EQ(H30,$H$2:$H$1116) -> 238 | J30: 619 | K30: 46 | L30: 20 | M30: 25 | N30: =J30+K30+L30+M30 -> 710 | O30: =IF(ISNUMBER(N30),N30,"") -> 710 | P30: =_xlfn.RANK.EQ(O30,$O$2:$O$1116) -> 199 | Q30: 273 | R30: 46 | S30: 22 | T30: 23 | U30: =Q30+R30+S30+T30 -> 364 | V30: =IF(ISNUMBER(U30),U30,"") -> 364 | W30: =_xlfn.RANK.EQ(V30,$V$2:$V$1116) -> 220 | Y30: =IF(ISNUMBER(X30),X30,"") | Z30: =_xlfn.RANK.EQ(Y30,$Y$2:$Y$1116) -> #VALUE! | AA30: =AB30/3180 -> 0.55455975 | AB30: =C30+D30+E30+F30+J30+K30+L30+M30+Q30+R30+S30+T30+X30 -> 1763.5 | AC30: =IF(ISNUMBER(AB30),AB30,"") -> 1763.5 | AD30: =_xlfn.RANK.EQ(AC30,$AC$2:$AC$1116) -> 205
A31: 75 | B31: احمد شريف فتحي عبدالفتاح | C31: 595.7 | D31: 22 | E31: 25 | F31: 23 | G31: =C31+D31+E31+F31 -> 665.7 | H31: =IF(ISNUMBER(G31),G31,"") -> 665.7 | I31: =_xlfn.RANK.EQ(H31,$H$2:$H$1116) -> 386 | J31: 615 | K31: 49 | L31: 21 | M31: 22 | N31: =J31+K31+L31+M31 -> 707 | O31: =IF(ISNUMBER(N31),N31,"") -> 707 | P31: =_xlfn.RANK.EQ(O31,$O$2:$O$1116) -> 226 | Q31: 272 | R31: 46.5 | S31: 24 | T31: 25 | U31: =Q31+R31+S31+T31 -> 367.5 | V31: =IF(ISNUMBER(U31),U31,"") -> 367.5 | W31: =_xlfn.RANK.EQ(V31,$V$2:$V$1116) -> 188 | Y31: =IF(ISNUMBER(X31),X31,"") | Z31: =_xlfn.RANK.EQ(Y31,$Y$2:$Y$1116) -> #VALUE! | AA31: =AB31/3180 -> 0.5472327 | AB31: =C31+D31+E31+F31+J31+K31+L31+M31+Q31+R31+S31+T31+X31 -> 1740.2 | AC31: =IF(ISNUMBER(AB31),AB31,"") -> 1740.2 | AD31: =_xlfn.RANK.EQ(AC31,$AC$2:$AC$1116) -> 271
A32: 76 | B32: احمد صابر السيد السعيد إبراهيم | C32: 598.1 | D32: 23 | E32: 24 | F32: 24 | G32: =C32+D32+E32+F32 -> 669.1 | H32: =IF(ISNUMBER(G32),G32,"") -> 669.1 | I32: =_xlfn.RANK.EQ(H32,$H$2:$H$1116) -> 367 | J32: 617 | K32: 50 | L32: 23 | M32: 20 | N32: =J32+K32+L32+M32 -> 710 | O32: =IF(ISNUMBER(N32),N32,"") -> 710 | P32: =_xlfn.RANK.EQ(O32,$O$2:$O$1116) -> 199 | Q32: 261 | R32: 47.5 | S32: 24 | T32: 25 | U32: =Q32+R32+S32+T32 -> 357.5 | V32: =IF(ISNUMBER(U32),U32,"") -> 357.5 | W32: =_xlfn.RANK.EQ(V32,$V$2:$V$1116) -> 287 | Y32: =IF(ISNUMBER(X32),X32,"") | Z32: =_xlfn.RANK.EQ(Y32,$Y$2:$Y$1116) -> #VALUE! | AA32: =AB32/3180 -> 0.54610063 | AB32: =C32+D32+E32+F32+J32+K32+L32+M32+Q32+R32+S32+T32+X32 -> 1736.6 | AC32: =IF(ISNUMBER(AB32),AB32,"") -> 1736.6 | AD32: =_xlfn.RANK.EQ(AC32,$AC$2:$AC$1116) -> 279
A33: 77 | B33: احمد صبحى درويش محمد موسى عشيبة | C33: 525.8 | D33: 23 | E33: 25 | F33: 22 | G33: =C33+D33+E33+F33 -> 595.8 | H33: =IF(ISNUMBER(G33),G33,"") -> 595.8 | I33: =_xlfn.RANK.EQ(H33,$H$2:$H$1116) -> 721 | J33: 562.5 | K33: 46 | L33: 21 | M33: 23 | N33: =J33+K33+L33+M33 -> 652.5 | O33: =IF(ISNUMBER(N33),N33,"") -> 652.5 | P33: =_xlfn.RANK.EQ(O33,$O$2:$O$1116) -> 569 | Q33: 263.5 | R33: 46.5 | S33: 24 | T33: 25 | U33: =Q33+R33+S33+T33 -> 359 | V33: =IF(ISNUMBER(U33),U33,"") -> 359 | W33: =_xlfn.RANK.EQ(V33,$V$2:$V$1116) -> 265 | Y33: =IF(ISNUMBER(X33),X33,"") | Z33: =_xlfn.RANK.EQ(Y33,$Y$2:$Y$1116) -> #VALUE! | AA33: =AB33/3180 -> 0.50544025 | AB33: =C33+D33+E33+F33+J33+K33+L33+M33+Q33+R33+S33+T33+X33 -> 1607.3 | AC33: =IF(ISNUMBER(AB33),AB33,"") -> 1607.3 | AD33: =_xlfn.RANK.EQ(AC33,$AC$2:$AC$1116) -> 574
... A41: 89 | B41: احمد عبد الناصر عبد السيد شاهين | C41: 584 | D41: 22 | E41: 17 | F41: 17 | G41: =C41+D41+E41+F41 -> 640 | H41: =IF(ISNUMBER(G41),G41,"") -> 640 | I41: =_xlfn.RANK.EQ(H41,$H$2:$H$1116) -> 534 | J41: 616.7 | K41: 47 | L41: 20 | M41: 20 | N41: =J41+K41+L41+M41 -> 703.7 | O41: =IF(ISNUMBER(N41),N41,"") -> 703.7 | P41: =_xlfn.RANK.EQ(O41,$O$2:$O$1116) -> 253 | Q41: 276 | R41: 45 | S41: 21 | T41: 21.5 | U41: =Q41+R41+S41+T41 -> 363.5 | V41: =IF(ISNUMBER(U41),U41,"") -> 363.5 | W41: =_xlfn.RANK.EQ(V41,$V$2:$V$1116) -> 224 | Y41: =IF(ISNUMBER(X41),X41,"") | Z41: =_xlfn.RANK.EQ(Y41,$Y$2:$Y$1116) -> #VALUE! | AA41: =AB41/3180 -> 0.53685535 | AB41: =C41+D41+E41+F41+J41+K41+L41+M41+Q41+R41+S41+T41+X41 -> 1707.2 | AC41: =IF(ISNUMBER(AB41),AB41,"") -> 1707.2 | AD41: =_xlfn.RANK.EQ(AC41,$AC$2:$AC$1116) -> 363
A42: 90 | B42: احمد عصام احمد على عبدالمطلب | C42: 450 | D42: 21 | E42: 19 | F42: 15 | G42: =C42+D42+E42+F42 -> 505 | H42: =IF(ISNUMBER(G42),G42,"") -> 505 | I42: =_xlfn.RANK.EQ(H42,$H$2:$H$1116) -> 941 | J42: 441.7 | K42: 25 | L42: 16 | M42: 8 | N42: =J42+K42+L42+M42 -> 490.7 | O42: =IF(ISNUMBER(N42),N42,"") -> 490.7 | P42: =_xlfn.RANK.EQ(O42,$O$2:$O$1116) -> 994 | Q42: راسب | R42: 35.5 | S42: 20 | T42: 22.5 | U42: =Q42+R42+S42+T42 -> #VALUE! | V42: =IF(ISNUMBER(U42),U42,"") | W42: =_xlfn.RANK.EQ(V42,$V$2:$V$1116) -> #VALUE! | Y42: =IF(ISNUMBER(X42),X42,"") | Z42: =_xlfn.RANK.EQ(Y42,$Y$2:$Y$1116) -> #VALUE! | AA42: =AB42/3180 -> #VALUE! | AB42: =C42+D42+E42+F42+J42+K42+L42+M42+Q42+R42+S42+T42+X42 -> #VALUE! | AC42: =IF(ISNUMBER(AB42),AB42,"") | AD42: =_xlfn.RANK.EQ(AC42,$AC$2:$AC$1116) -> #VALUE!
A43: 91 | B43: احمد عصام محمد الشيخ | C43: 638.6 | D43: 25 | E43: 24 | F43: 24 | G43: =C43+D43+E43+F43 -> 711.6 | H43: =IF(ISNUMBER(G43),G43,"") -> 711.6 | I43: =_xlfn.RANK.EQ(H43,$H$2:$H$1116) -> 104 | J43: 631 | K43: 49 | L43: 23 | M43: 25 | N43: =J43+K43+L43+M43 -> 728 | O43: =IF(ISNUMBER(N43),N43,"") -> 728 | P43: =_xlfn.RANK.EQ(O43,$O$2:$O$1116) -> 63 | Q43: 283 | R43: 48.5 | S43: 25 | T43: 25 | U43: =Q43+R43+S43+T43 -> 381.5 | V43: =IF(ISNUMBER(U43),U43,"") -> 381.5 | W43: =_xlfn.RANK.EQ(V43,$V$2:$V$1116) -> 54 | Y43: =IF(ISNUMBER(X43),X43,"") | Z43: =_xlfn.RANK.EQ(Y43,$Y$2:$Y$1116) -> #VALUE! | AA43: =AB43/3180 -> 0.57267296 | AB43: =C43+D43+E43+F43+J43+K43+L43+M43+Q43+R43+S43+T43+X43 -> 1821.1 | AC43: =IF(ISNUMBER(AB43),AB43,"") -> 1821.1 | AD43: =_xlfn.RANK.EQ(AC43,$AC$2:$AC$1116) -> 68
A44: 93 | B44: احمد عصام محمود عبدالحميد الرسول | C44: 550.6 | D44: 22 | E44: 23 | F44: 22 | G44: =C44+D44+E44+F44 -> 617.6 | H44: =IF(ISNUMBER(G44),G44,"") -> 617.6 | I44: =_xlfn.RANK.EQ(H44,$H$2:$H$1116) -> 643 | J44: 549.5 | K44: 39 | L44: 20 | M44: 19 | N44: =J44+K44+L44+M44 -> 627.5 | O44: =IF(ISNUMBER(N44),N44,"") -> 627.5 | P44: =_xlfn.RANK.EQ(O44,$O$2:$O$1116) -> 712 | Q44: راسب | S44: 22 | T44: 23.5 | U44: =Q44+R44+S44+T44 -> #VALUE! | V44: =IF(ISNUMBER(U44),U44,"") | W44: =_xlfn.RANK.EQ(V44,$V$2:$V$1116) -> #VALUE! | Y44: =IF(ISNUMBER(X44),X44,"") | Z44: =_xlfn.RANK.EQ(Y44,$Y$2:$Y$1116) -> #VALUE! | AA44: =AB44/3180 -> #VALUE! | AB44: =C44+D44+E44+F44+J44+K44+L44+M44+Q44+R44+S44+T44+X44 -> #VALUE! | AC44: =IF(ISNUMBER(AB44),AB44,"") | AD44: =_xlfn.RANK.EQ(AC44,$AC$2:$AC$1116) -> #VALUE!
A45: 95 | B45: احمد علاء كامل محمد علي جنيدي | C45: 539.8 | D45: 21 | E45: 20 | F45: 20 | G45: =C45+D45+E45+F45 -> 600.8 | H45: =IF(ISNUMBER(G45),G45,"") -> 600.8 | I45: =_xlfn.RANK.EQ(H45,$H$2:$H$1116) -> 705 | J45: 531 | K45: 49 | L45: 20 | M45: 25 | N45: =J45+K45+L45+M45 -> 625 | O45: =IF(ISNUMBER(N45),N45,"") -> 625 | P45: =_xlfn.RANK.EQ(O45,$O$2:$O$1116) -> 720 | Q45: 222 | R45: 48 | S45: 25 | T45: 18 | U45: =Q45+R45+S45+T45 -> 313 | V45: =IF(ISNUMBER(U45),U45,"") -> 313 | W45: =_xlfn.RANK.EQ(V45,$V$2:$V$1116) -> 705 | Y45: =IF(ISNUMBER(X45),X45,"") | Z45: =_xlfn.RANK.EQ(Y45,$Y$2:$Y$1116) -> #VALUE! | AA45: =AB45/3180 -> 0.48389937 | AB45: =C45+D45+E45+F45+J45+K45+L45+M45+Q45+R45+S45+T45+X45 -> 1538.8 | AC45: =IF(ISNUMBER(AB45),AB45,"") -> 1538.8 | AD45: =_xlfn.RANK.EQ(AC45,$AC$2:$AC$1116) -> 691
A46: 97 | B46: احمد عماد الدين شاكر مصطفى | C46: 413.75 | D46: 15 | E46: 13 | F46: 18 | G46: =C46+D46+E46+F46 -> 459.75 | H46: =IF(ISNUMBER(G46),G46,"") -> 459.75 | I46: =_xlfn.RANK.EQ(H46,$H$2:$H$1116) -> 997 | J46: 480.7 | K46: 46 | L46: 18 | M46: 15 | N46: =J46+K46+L46+M46 -> 559.7 | O46: =IF(ISNUMBER(N46),N46,"") -> 559.7 | P46: =_xlfn.RANK.EQ(O46,$O$2:$O$1116) -> 881 | Q46: راسب | R46: 31 | S46: 25 | T46: 24 | U46: =Q46+R46+S46+T46 -> #VALUE! | V46: =IF(ISNUMBER(U46),U46,"") | W46: =_xlfn.RANK.EQ(V46,$V$2:$V$1116) -> #VALUE! | Y46: =IF(ISNUMBER(X46),X46,"") | Z46: =_xlfn.RANK.EQ(Y46,$Y$2:$Y$1116) -> #VALUE! | AA46: =AB46/3180 -> #VALUE! | AB46: =C46+D46+E46+F46+J46+K46+L46+M46+Q46+R46+S46+T46+X46 -> #VALUE! | AC46: =IF(ISNUMBER(AB46),AB46,"") | AD46: =_xlfn.RANK.EQ(AC46,$AC$2:$AC$1116) -> #VALUE!
A47: 100 | B47: احمد عمرو عبد العظيم حبيب | C47: 578.6 | D47: 22 | E47: 22 | F47: 18 | G47: =C47+D47+E47+F47 -> 640.6 | H47: =IF(ISNUMBER(G47),G47,"") -> 640.6 | I47: =_xlfn.RANK.EQ(H47,$H$2:$H$1116) -> 529 | J47: 599.1 | K47: 42 | L47: 20 | M47: 22 | N47: =J47+K47+L47+M47 -> 683.1 | O47: =IF(ISNUMBER(N47),N47,"") -> 683.1 | P47: =_xlfn.RANK.EQ(O47,$O$2:$O$1116) -> 402 | Q47: 270.5 | R47: 41 | S47: 24 | T47: 23.5 | U47: =Q47+R47+S47+T47 -> 359 | V47: =IF(ISNUMBER(U47),U47,"") -> 359 | W47: =_xlfn.RANK.EQ(V47,$V$2:$V$1116) -> 265 | Y47: =IF(ISNUMBER(X47),X47,"") | Z47: =_xlfn.RANK.EQ(Y47,$Y$2:$Y$1116) -> #VALUE! | AA47: =AB47/3180 -> 0.52915094 | AB47: =C47+D47+E47+F47+J47+K47+L47+M47+Q47+R47+S47+T47+X47 -> 1682.7 | AC47: =IF(ISNUMBER(AB47),AB47,"") -> 1682.7 | AD47: =_xlfn.RANK.EQ(AC47,$AC$2:$AC$1116) -> 414
A48: 101 | B48: احمد عيد عبدالمقصود محمد جادالله | C48: 609.1 | D48: 24 | E48: 20 | F48: 19 | G48: =C48+D48+E48+F48 -> 672.1 | H48: =IF(ISNUMBER(G48),G48,"") -> 672.1 | I48: =_xlfn.RANK.EQ(H48,$H$2:$H$1116) -> 348 | J48: 572.5 | K48: 45 | L48: 19 | M48: 17 | N48: =J48+K48+L48+M48 -> 653.5 | O48: =IF(ISNUMBER(N48),N48,"") -> 653.5 | P48: =_xlfn.RANK.EQ(O48,$O$2:$O$1116) -> 563 | Q48: 243 | R48: 44 | S48: 19 | T48: 24.5 | U48: =Q48+R48+S48+T48 -> 330.5 | V48: =IF(ISNUMBER(U48),U48,"") -> 330.5 | W48: =_xlfn.RANK.EQ(V48,$V$2:$V$1116) -> 556 | Y48: =IF(ISNUMBER(X48),X48,"") | Z48: =_xlfn.RANK.EQ(Y48,$Y$2:$Y$1116) -> #VALUE! | AA48: =AB48/3180 -> 0.52078616 | AB48: =C48+D48+E48+F48+J48+K48+L48+M48+Q48+R48+S48+T48+X48 -> 1656.1 | AC48: =IF(ISNUMBER(AB48),AB48,"") -> 1656.1 | AD48: =_xlfn.RANK.EQ(AC48,$AC$2:$AC$1116) -> 471
A49: 107 | B49: احمد فرج الله خضر احمد عبد العال | C49: 628.6 | D49: 25 | E49: 24 | F49: 25 | G49: =C49+D49+E49+F49 -> 702.6 | H49: =IF(ISNUMBER(G49),G49,"") -> 702.6 | I49: =_xlfn.RANK.EQ(H49,$H$2:$H$1116) -> 155 | J49: 611.4 | K49: 50 | L49: 21 | M49: 22 | N49: =J49+K49+L49+M49 -> 704.4 | O49: =IF(ISNUMBER(N49),N49,"") -> 704.4 | P49: =_xlfn.RANK.EQ(O49,$O$2:$O$1116) -> 246 | Q49: 271 | R49: 47.5 | S49: 25 | T49: 24.5 | U49: =Q49+R49+S49+T49 -> 368 | V49: =IF(ISNUMBER(U49),U49,"") -> 368 | W49: =_xlfn.RANK.EQ(V49,$V$2:$V$1116) -> 182 | Y49: =IF(ISNUMBER(X49),X49,"") | Z49: =_xlfn.RANK.EQ(Y49,$Y$2:$Y$1116) -> #VALUE! | AA49: =AB49/3180 -> 0.5581761 | AB49: =C49+D49+E49+F49+J49+K49+L49+M49+Q49+R49+S49+T49+X49 -> 1775 | AC49: =IF(ISNUMBER(AB49),AB49,"") -> 1775 | AD49: =_xlfn.RANK.EQ(AC49,$AC$2:$AC$1116) -> 176
A50: 109 | B50: احمد كارم محمود السيد الجميعى | C50: 591.1 | D50: 23 | E50: 24 | F50: 21 | G50: =C50+D50+E50+F50 -> 659.1 | H50: =IF(ISNUMBER(G50),G50,"") -> 659.1 | I50: =_xlfn.RANK.EQ(H50,$H$2:$H$1116) -> 435 | J50: 600.3 | K50: 48 | L50: 22 | M50: 24 | N50: =J50+K50+L50+M50 -> 694.3 | O50: =IF(ISNUMBER(N50),N50,"") -> 694.3 | P50: =_xlfn.RANK.EQ(O50,$O$2:$O$1116) -> 328 | Q50: 264 | R50: 48 | S50: 23 | T50: 23.5 | U50: =Q50+R50+S50+T50 -> 358.5 | V50: =IF(ISNUMBER(U50),U50,"") -> 358.5 | W50: =_xlfn.RANK.EQ(V50,$V$2:$V$1116) -> 275 | Y50: =IF(ISNUMBER(X50),X50,"") | Z50: =_xlfn.RANK.EQ(Y50,$Y$2:$Y$1116) -> #VALUE! | AA50: =AB50/3180 -> 0.53833333 | AB50: =C50+D50+E50+F50+J50+K50+L50+M50+Q50+R50+S50+T50+X50 -> 1711.9 | AC50: =IF(ISNUMBER(AB50),AB50,"") -> 1711.9 | AD50: =_xlfn.RANK.EQ(AC50,$AC$2:$AC$1116) -> 353
A51: 110 | B51: احمد كريم ابراهيم خليل شرشر | C51: 460.25 | D51: 19 | E51: 17 | F51: 23 | G51: =C51+D51+E51+F51 -> 519.25 | H51: =IF(ISNUMBER(G51),G51,"") -> 519.25 | I51: =_xlfn.RANK.EQ(H51,$H$2:$H$1116) -> 914 | J51: 421.2 | K51: 49 | L51: 20 | M51: 18 | N51: =J51+K51+L51+M51 -> 508.2 | O51: =IF(ISNUMBER(N51),N51,"") -> 508.2 | P51: =_xlfn.RANK.EQ(O51,$O$2:$O$1116) -> 971 | Q51: 199.75 | R51: 41.5 | S51: 24 | T51: 21.5 | U51: =Q51+R51+S51+T51 -> 286.75 | V51: =IF(ISNUMBER(U51),U51,"") -> 286.75 | W51: =_xlfn.RANK.EQ(V51,$V$2:$V$1116) -> 861 | Y51: =IF(ISNUMBER(X51),X51,"") | Z51: =_xlfn.RANK.EQ(Y51,$Y$2:$Y$1116) -> #VALUE! | AA51: =AB51/3180 -> 0.41327044 | AB51: =C51+D51+E51+F51+J51+K51+L51+M51+Q51+R51+S51+T51+X51 -> 1314.2 | AC51: =IF(ISNUMBER(AB51),AB51,"") -> 1314.2 | AD51: =_xlfn.RANK.EQ(AC51,$AC$2:$AC$1116) -> 915
A52: 112 | B52: احمد ماهر ابراهيم الدسوقى محمد الشحات | C52: 604.6 | D52: 25 | E52: 25 | F52: 24 | G52: =C52+D52+E52+F52 -> 678.6 | H52: =IF(ISNUMBER(G52),G52,"") -> 678.6 | I52: =_xlfn.RANK.EQ(H52,$H$2:$H$1116) -> 305 | J52: 604.9 | K52: 48 | L52: 21 | M52: 22 | N52: =J52+K52+L52+M52 -> 695.9 | O52: =IF(ISNUMBER(N52),N52,"") -> 695.9 | P52: =_xlfn.RANK.EQ(O52,$O$2:$O$1116) -> 315 | Q52: 279 | R52: 48.5 | S52: 25 | T52: 24 | U52: =Q52+R52+S52+T52 -> 376.5 | V52: =IF(ISNUMBER(U52),U52,"") -> 376.5 | W52: =_xlfn.RANK.EQ(V52,$V$2:$V$1116) -> 94 | Y52: =IF(ISNUMBER(X52),X52,"") | Z52: =_xlfn.RANK.EQ(Y52,$Y$2:$Y$1116) -> #VALUE! | AA52: =AB52/3180 -> 0.55062893 | AB52: =C52+D52+E52+F52+J52+K52+L52+M52+Q52+R52+S52+T52+X52 -> 1751 | AC52: =IF(ISNUMBER(AB52),AB52,"") -> 1751 | AD52: =_xlfn.RANK.EQ(AC52,$AC$2:$AC$1116) -> 229
A53: 115 | B53: احمد متولي محمد متولي | C53: 512.9 | D53: 22 | E53: 22 | F53: 22 | G53: =C53+D53+E53+F53 -> 578.9 | H53: =IF(ISNUMBER(G53),G53,"") -> 578.9 | I53: =_xlfn.RANK.EQ(H53,$H$2:$H$1116) -> 767 | J53: 534.6 | K53: 35 | L53: 23 | M53: 18 | N53: =J53+K53+L53+M53 -> 610.6 | O53: =IF(ISNUMBER(N53),N53,"") -> 610.6 | P53: =_xlfn.RANK.EQ(O53,$O$2:$O$1116) -> 761 | Q53: 206 | R53: 38 | S53: 21 | T53: 21.5 | U53: =Q53+R53+S53+T53 -> 286.5 | V53: =IF(ISNUMBER(U53),U53,"") -> 286.5 | W53: =_xlfn.RANK.EQ(V53,$V$2:$V$1116) -> 862 | Y53: =IF(ISNUMBER(X53),X53,"") | Z53: =_xlfn.RANK.EQ(Y53,$Y$2:$Y$1116) -> #VALUE! | AA53: =AB53/3180 -> 0.46415094 | AB53: =C53+D53+E53+F53+J53+K53+L53+M53+Q53+R53+S53+T53+X53 -> 1476 | AC53: =IF(ISNUMBER(AB53),AB53,"") -> 1476 | AD53: =_xlfn.RANK.EQ(AC53,$AC$2:$AC$1116) -> 778
...
