Workbook

Sheet Sheet3
A1: ID | D1: 2 | G1: 3 | H1: 4
A2: 4 | B2: =Sheet1!C2+Sheet1!D2+Sheet1!E2+Sheet1!F2+Sheet1!J2+Sheet1!K2+Sheet1!L2+Sheet1!M2 | C2: =IF(ISNUMBER(B2),B2,"") | D2: =IF(ISNUMBER(C2),_xlfn.RANK.EQ(C2,$C$2:$C$1031),"") | E2: =Sheet1!C2+Sheet1!D2+Sheet1!E2+Sheet1!F2+Sheet1!J2+Sheet1!K2+Sheet1!L2+Sheet1!M2+Sheet1!Q2+Sheet1!R2+Sheet1!S2+Sheet1!T2 | F2: =IF(ISNUMBER(E2),E2,"") | G2: =IF(ISNUMBER(F2),_xlfn.RANK.EQ(F2,$F$2:$F$1031),"") | H2: =INDEX(Sheet1!AH:AH,MATCH(A2,Sheet1!A:A,0))
A3: 6 | B3: =Sheet1!C3+Sheet1!D3+Sheet1!E3+Sheet1!F3+Sheet1!J3+Sheet1!K3+Sheet1!L3+Sheet1!M3 | C3: =IF(ISNUMBER(B3),B3,"") | D3: =IF(ISNUMBER(C3),_xlfn.RANK.EQ(C3,$C$2:$C$1031),"") | E3: =Sheet1!C3+Sheet1!D3+Sheet1!E3+Sheet1!F3+Sheet1!J3+Sheet1!K3+Sheet1!L3+Sheet1!M3+Sheet1!Q3+Sheet1!R3+Sheet1!S3+Sheet1!T3 | F3: =IF(ISNUMBER(E3),E3,"") | G3: =IF(ISNUMBER(F3),_xlfn.RANK.EQ(F3,$F$2:$F$1031),"") | H3: =INDEX(Sheet1!AH:AH,MATCH(A3,Sheet1!A:A,0))
A4: 9 | B4: =Sheet1!C4+Sheet1!D4+Sheet1!E4+Sheet1!F4+Sheet1!J4+Sheet1!K4+Sheet1!L4+Sheet1!M4 | C4: =IF(ISNUMBER(B4),B4,"") | D4: =IF(ISNUMBER(C4),_xlfn.RANK.EQ(C4,$C$2:$C$1031),"") | E4: =Sheet1!C4+Sheet1!D4+Sheet1!E4+Sheet1!F4+Sheet1!J4+Sheet1!K4+Sheet1!L4+Sheet1!M4+Sheet1!Q4+Sheet1!R4+Sheet1!S4+Sheet1!T4 | F4: =IF(ISNUMBER(E4),E4,"") | G4: =IF(ISNUMBER(F4),_xlfn.RANK.EQ(F4,$F$2:$F$1031),"") | H4: =INDEX(Sheet1!AH:AH,MATCH(A4,Sheet1!A:A,0))
A5: 13 | B5: =Sheet1!C5+Sheet1!D5+Sheet1!E5+Sheet1!F5+Sheet1!J5+Sheet1!K5+Sheet1!L5+Sheet1!M5 | C5: =IF(ISNUMBER(B5),B5,"") | D5: =IF(ISNUMBER(C5),_xlfn.RANK.EQ(C5,$C$2:$C$1031),"") | E5: =Sheet1!C5+Sheet1!D5+Sheet1!E5+Sheet1!F5+Sheet1!J5+Sheet1!K5+Sheet1!L5+Sheet1!M5+Sheet1!Q5+Sheet1!R5+Sheet1!S5+Sheet1!T5 | F5: =IF(ISNUMBER(E5),E5,"") | G5: =IF(ISNUMBER(F5),_xlfn.RANK.EQ(F5,$F$2:$F$1031),"") | H5: =INDEX(Sheet1!AH:AH,MATCH(A5,Sheet1!A:A,0))
A6: 15 | B6: =Sheet1!C6+Sheet1!D6+Sheet1!E6+Sheet1!F6+Sheet1!J6+Sheet1!K6+Sheet1!L6+Sheet1!M6 | C6: =IF(ISNUMBER(B6),B6,"") | D6: =IF(ISNUMBER(C6),_xlfn.RANK.EQ(C6,$C$2:$C$1031),"") | E6: =Sheet1!C6+Sheet1!D6+Sheet1!E6+Sheet1!F6+Sheet1!J6+Sheet1!K6+Sheet1!L6+Sheet1!M6+Sheet1!Q6+Sheet1!R6+Sheet1!S6+Sheet1!T6 | F6: =IF(ISNUMBER(E6),E6,"") | G6: =IF(ISNUMBER(F6),_xlfn.RANK.EQ(F6,$F$2:$F$1031),"") | H6: =INDEX(Sheet1!AH:AH,MATCH(A6,Sheet1!A:A,0))
A7: 31 | B7: =Sheet1!C7+Sheet1!D7+Sheet1!E7+Sheet1!F7+Sheet1!J7+Sheet1!K7+Sheet1!L7+Sheet1!M7 | C7: =IF(ISNUMBER(B7),B7,"") | D7: =IF(ISNUMBER(C7),_xlfn.RANK.EQ(C7,$C$2:$C$1031),"") | E7: =Sheet1!C7+Sheet1!D7+Sheet1!E7+Sheet1!F7+Sheet1!J7+Sheet1!K7+Sheet1!L7+Sheet1!M7+Sheet1!Q7+Sheet1!R7+Sheet1!S7+Sheet1!T7 | F7: =IF(ISNUMBER(E7),E7,"") | G7: =IF(ISNUMBER(F7),_xlfn.RANK.EQ(F7,$F$2:$F$1031),"") | H7: =INDEX(Sheet1!AH:AH,MATCH(A7,Sheet1!A:A,0))
A8: 32 | B8: =Sheet1!C8+Sheet1!D8+Sheet1!E8+Sheet1!F8+Sheet1!J8+Sheet1!K8+Sheet1!L8+Sheet1!M8 | C8: =IF(ISNUMBER(B8),B8,"") | D8: =IF(ISNUMBER(C8),_xlfn.RANK.EQ(C8,$C$2:$C$1031),"") | E8: =Sheet1!C8+Sheet1!D8+Sheet1!E8+Sheet1!F8+Sheet1!J8+Sheet1!K8+Sheet1!L8+Sheet1!M8+Sheet1!Q8+Sheet1!R8+Sheet1!S8+Sheet1!T8 | F8: =IF(ISNUMBER(E8),E8,"") | G8: =IF(ISNUMBER(F8),_xlfn.RANK.EQ(F8,$F$2:$F$1031),"") | H8: =INDEX(Sheet1!AH:AH,MATCH(A8,Sheet1!A:A,0))
A9: 34 | B9: =Sheet1!C9+Sheet1!D9+Sheet1!E9+Sheet1!F9+Sheet1!J9+Sheet1!K9+Sheet1!L9+Sheet1!M9 | C9: =IF(ISNUMBER(B9),B9,"") | D9: =IF(ISNUMBER(C9),_xlfn.RANK.EQ(C9,$C$2:$C$1031),"") | E9: =Sheet1!C9+Sheet1!D9+Sheet1!E9+Sheet1!F9+Sheet1!J9+Sheet1!K9+Sheet1!L9+Sheet1!M9+Sheet1!Q9+Sheet1!R9+Sheet1!S9+Sheet1!T9 | F9: =IF(ISNUMBER(E9),E9,"") | G9: =IF(ISNUMBER(F9),_xlfn.RANK.EQ(F9,$F$2:$F$1031),"") | H9: =INDEX(Sheet1!AH:AH,MATCH(A9,Sheet1!A:A,0))
A10: 35 | B10: =Sheet1!C10+Sheet1!D10+Sheet1!E10+Sheet1!F10+Sheet1!J10+Sheet1!K10+Sheet1!L10+Sheet1!M10 | C10: =IF(ISNUMBER(B10),B10,"") | D10: =IF(ISNUMBER(C10),_xlfn.RANK.EQ(C10,$C$2:$C$1031),"") | E10: =Sheet1!C10+Sheet1!D10+Sheet1!E10+Sheet1!F10+Sheet1!J10+Sheet1!K10+Sheet1!L10+Sheet1!M10+Sheet1!Q10+Sheet1!R10+Sheet1!S10+Sheet1!T10 | F10: =IF(ISNUMBER(E10),E10,"") | G10: =IF(ISNUMBER(F10),_xlfn.RANK.EQ(F10,$F$2:$F$1031),"") | H10: =INDEX(Sheet1!AH:AH,MATCH(A10,Sheet1!A:A,0))
A11: 37 | B11: =Sheet1!C11+Sheet1!D11+Sheet1!E11+Sheet1!F11+Sheet1!J11+Sheet1!K11+Sheet1!L11+Sheet1!M11 | C11: =IF(ISNUMBER(B11),B11,"") | D11: =IF(ISNUMBER(C11),_xlfn.RANK.EQ(C11,$C$2:$C$1031),"") | E11: =Sheet1!C11+Sheet1!D11+Sheet1!E11+Sheet1!F11+Sheet1!J11+Sheet1!K11+Sheet1!L11+Sheet1!M11+Sheet1!Q11+Sheet1!R11+Sheet1!S11+Sheet1!T11 | F11: =IF(ISNUMBER(E11),E11,"") | G11: =IF(ISNUMBER(F11),_xlfn.RANK.EQ(F11,$F$2:$F$1031),"") | H11: =INDEX(Sheet1!AH:AH,MATCH(A11,Sheet1!A:A,0))
A12: 38 | B12: =Sheet1!C12+Sheet1!D12+Sheet1!E12+Sheet1!F12+Sheet1!J12+Sheet1!K12+Sheet1!L12+Sheet1!M12 | C12: =IF(ISNUMBER(B12),B12,"") | D12: =IF(ISNUMBER(C12),_xlfn.RANK.EQ(C12,$C$2:$C$1031),"") | E12: =Sheet1!C12+Sheet1!D12+Sheet1!E12+Sheet1!F12+Sheet1!J12+Sheet1!K12+Sheet1!L12+Sheet1!M12+Sheet1!Q12+Sheet1!R12+Sheet1!S12+Sheet1!T12 | F12: =IF(ISNUMBER(E12),E12,"") | G12: =IF(ISNUMBER(F12),_xlfn.RANK.EQ(F12,$F$2:$F$1031),"") | H12: =INDEX(Sheet1!AH:AH,MATCH(A12,Sheet1!A:A,0))
A13: 39 | B13: =Sheet1!C13+Sheet1!D13+Sheet1!E13+Sheet1!F13+Sheet1!J13+Sheet1!K13+Sheet1!L13+Sheet1!M13 | C13: =IF(ISNUMBER(B13),B13,"") | D13: =IF(ISNUMBER(C13),_xlfn.RANK.EQ(C13,$C$2:$C$1031),"") | E13: =Sheet1!C13+Sheet1!D13+Sheet1!E13+Sheet1!F13+Sheet1!J13+Sheet1!K13+Sheet1!L13+Sheet1!M13+Sheet1!Q13+Sheet1!R13+Sheet1!S13+Sheet1!T13 | F13: =IF(ISNUMBER(E13),E13,"") | G13: =IF(ISNUMBER(F13),_xlfn.RANK.EQ(F13,$F$2:$F$1031),"") | H13: =INDEX(Sheet1!AH:AH,MATCH(A13,Sheet1!A:A,0))
... A1031: 2603 | B1031: =Sheet1!C1031+Sheet1!D1031+Sheet1!E1031+Sheet1!F1031+Sheet1!J1031+Sheet1!K1031+Sheet1!L1031+Sheet1!M1031 | C1031: =IF(ISNUMBER(B1031),B1031,"") | D1031: =IF(ISNUMBER(C1031),_xlfn.RANK.EQ(C1031,$C$2:$C$1031),"") | E1031: =Sheet1!C1031+Sheet1!D1031+Sheet1!E1031+Sheet1!F1031+Sheet1!J1031+Sheet1!K1031+Sheet1!L1031+Sheet1!M1031+Sheet1!Q1031+Sheet1!R1031+Sheet1!S1031+Sheet1!T1031 | F1031: =IF(ISNUMBER(E1031),E1031,"") | G1031: =IF(ISNUMBER(F1031),_xlfn.RANK.EQ(F1031,$F$2:$F$1031),"") | H1031: =INDEX(Sheet1!AH:AH,MATCH(A1031,Sheet1!A:A,0))

Sheet Sheet2
A1: ID | B1: FIRST YEAR RANK | C1: SECOND YEAR RANK C | D1: THIRD YEAR RANK C | E1: FOURTH YEAR RANK C
A2: 4 | B2: =IFERROR(INDEX(Sheet1!I:I,MATCH(A2,Sheet1!A:A,0)),"") | C2: =IFERROR(INDEX(Sheet3!D:D,MATCH(A2,Sheet3!A:A,0)),"") | D2: =IFERROR(INDEX(Sheet3!G:G,MATCH(A2,Sheet3!A:A,0)),"") | E2: =IFERROR(INDEX(Sheet3!H:H,MATCH(A2,Sheet3!A:A,0)),"")
A3: 6 | B3: =IFERROR(INDEX(Sheet1!I:I,MATCH(A3,Sheet1!A:A,0)),"") | C3: =IFERROR(INDEX(Sheet3!D:D,MATCH(A3,Sheet3!A:A,0)),"") | D3: =IFERROR(INDEX(Sheet3!G:G,MATCH(A3,Sheet3!A:A,0)),"") | E3: =IFERROR(INDEX(Sheet3!H:H,MATCH(A3,Sheet3!A:A,0)),"")
A4: 9 | B4: =IFERROR(INDEX(Sheet1!I:I,MATCH(A4,Sheet1!A:A,0)),"") | C4: =IFERROR(INDEX(Sheet3!D:D,MATCH(A4,Sheet3!A:A,0)),"") | D4: =IFERROR(INDEX(Sheet3!G:G,MATCH(A4,Sheet3!A:A,0)),"") | E4: =IFERROR(INDEX(Sheet3!H:H,MATCH(A4,Sheet3!A:A,0)),"")
A5: 13 | B5: =IFERROR(INDEX(Sheet1!I:I,MATCH(A5,Sheet1!A:A,0)),"") | C5: =IFERROR(INDEX(Sheet3!D:D,MATCH(A5,Sheet3!A:A,0)),"") | D5: =IFERROR(INDEX(Sheet3!G:G,MATCH(A5,Sheet3!A:A,0)),"") | E5: =IFERROR(INDEX(Sheet3!H:H,MATCH(A5,Sheet3!A:A,0)),"")
A6: 15 | B6: =IFERROR(INDEX(Sheet1!I:I,MATCH(A6,Sheet1!A:A,0)),"") | C6: =IFERROR(INDEX(Sheet3!D:D,MATCH(A6,Sheet3!A:A,0)),"") | D6: =IFERROR(INDEX(Sheet3!G:G,MATCH(A6,Sheet3!A:A,0)),"") | E6: =IFERROR(INDEX(Sheet3!H:H,MATCH(A6,Sheet3!A:A,0)),"")
A7: 31 | B7: =IFERROR(INDEX(Sheet1!I:I,MATCH(A7,Sheet1!A:A,0)),"") | C7: =IFERROR(INDEX(Sheet3!D:D,MATCH(A7,Sheet3!A:A,0)),"") | D7: =IFERROR(INDEX(Sheet3!G:G,MATCH(A7,Sheet3!A:A,0)),"") | E7: =IFERROR(INDEX(Sheet3!H:H,MATCH(A7,Sheet3!A:A,0)),"")
A8: 32 | B8: =IFERROR(INDEX(Sheet1!I:I,MATCH(A8,Sheet1!A:A,0)),"") | C8: =IFERROR(INDEX(Sheet3!D:D,MATCH(A8,Sheet3!A:A,0)),"") | D8: =IFERROR(INDEX(Sheet3!G:G,MATCH(A8,Sheet3!A:A,0)),"") | E8: =IFERROR(INDEX(Sheet3!H:H,MATCH(A8,Sheet3!A:A,0)),"")
A9: 34 | B9: =IFERROR(INDEX(Sheet1!I:I,MATCH(A9,Sheet1!A:A,0)),"") | C9: =IFERROR(INDEX(Sheet3!D:D,MATCH(A9,Sheet3!A:A,0)),"") | D9: =IFERROR(INDEX(Sheet3!G:G,MATCH(A9,Sheet3!A:A,0)),"") | E9: =IFERROR(INDEX(Sheet3!H:H,MATCH(A9,Sheet3!A:A,0)),"")
A10: 35 | B10: =IFERROR(INDEX(Sheet1!I:I,MATCH(A10,Sheet1!A:A,0)),"") | C10: =IFERROR(INDEX(Sheet3!D:D,MATCH(A10,Sheet3!A:A,0)),"") | D10: =IFERROR(INDEX(Sheet3!G:G,MATCH(A10,Sheet3!A:A,0)),"") | E10: =IFERROR(INDEX(Sheet3!H:H,MATCH(A10,Sheet3!A:A,0)),"")
A11: 37 | B11: =IFERROR(INDEX(Sheet1!I:I,MATCH(A11,Sheet1!A:A,0)),"") | C11: =IFERROR(INDEX(Sheet3!D:D,MATCH(A11,Sheet3!A:A,0)),"") | D11: =IFERROR(INDEX(Sheet3!G:G,MATCH(A11,Sheet3!A:A,0)),"") | E11: =IFERROR(INDEX(Sheet3!H:H,MATCH(A11,Sheet3!A:A,0)),"")
A12: 38 | B12: =IFERROR(INDEX(Sheet1!I:I,MATCH(A12,Sheet1!A:A,0)),"") | C12: =IFERROR(INDEX(Sheet3!D:D,MATCH(A12,Sheet3!A:A,0)),"") | D12: =IFERROR(INDEX(Sheet3!G:G,MATCH(A12,Sheet3!A:A,0)),"") | E12: =IFERROR(INDEX(Sheet3!H:H,MATCH(A12,Sheet3!A:A,0)),"")
A13: 39 | B13: =IFERROR(INDEX(Sheet1!I:I,MATCH(A13,Sheet1!A:A,0)),"") | C13: =IFERROR(INDEX(Sheet3!D:D,MATCH(A13,Sheet3!A:A,0)),"") | D13: =IFERROR(INDEX(Sheet3!G:G,MATCH(A13,Sheet3!A:A,0)),"") | E13: =IFERROR(INDEX(Sheet3!H:H,MATCH(A13,Sheet3!A:A,0)),"")
... A1031: 2603 | B1031: =IFERROR(INDEX(Sheet1!I:I,MATCH(A1031,Sheet1!A:A,0)),"") | C1031: =IFERROR(INDEX(Sheet3!D:D,MATCH(A1031,Sheet3!A:A,0)),"") | D1031: =IFERROR(INDEX(Sheet3!G:G,MATCH(A1031,Sheet3!A:A,0)),"") | E1031: =IFERROR(INDEX(Sheet3!H:H,MATCH(A1031,Sheet3!A:A,0)),"")

Sheet Sheet1
A1: ID | B1: NAME | C1: FIRST YEAR | D1: PROFESSIONALISM STEP I | E1: RESEARCH STEP I | F1: COMMUNICATION STEP I | I1: FIRST YEAR RANK | J1: SECOND YEAR | K1: RESEARCH STEP II | L1: PROFESSIONALISM STEP II | M1: COMMUNICATION STEP II | P1: SECOND YEAR RANK | Q1: THIRD YEAR | R1: RESEARCH STEP III | S1: COMMUNICATION STEP III | T1: PROFESSIONALISM STEP III | W1: THIRD YEAR RANK | X1: FOURTH YEAR | Y1: PROFESSIONALISM STEP IV | Z1: RESEARCH STEP IV | AA1: COMMUNICATION STEP IV | AD1: FOURTH YEAR RANK | AE1: PERCENTAGE | AF1: TOTAL | AH1: TOTAL RANK
A2: 4 | B2: ابرار عدلى ابراهيم على بيبرس | C2: 596.9 | D2: 23 | E2: 23 | F2: 22 | G2: =C2+D2+E2+F2 | H2: =IF(ISNUMBER(G2),G2,"") | I2: =_xlfn.RANK.EQ(H2,$H$2:$H$1031) | J2: 577 | K2: 47 | L2: 22 | M2: 21 | N2: =J2+K2+L2+M2 | O2: =IF(ISNUMBER(N2),N2,"") | P2: =_xlfn.RANK.EQ(O2,$O$2:$O$1031) | Q2: 252.5 | R2: 46.5 | S2: 21 | T2: 23 | U2: =Q2+R2+S2+T2 | V2: =IF(ISNUMBER(U2),U2,"") | W2: =_xlfn.RANK.EQ(V2,$V$2:$V$1031) | X2: 1354.1958 | Y2: 24 | Z2: 25 | AA2: 21 | AB2: =IF(ISNUMBER(X2),X2+N(Y2)+N(Z2)+N(AA2),X2) | AC2: =IF(ISNUMBER(AB2),AB2,"") | AD2: =IF(ISNUMBER(AC2),_xlfn.RANK.EQ(AC2,$AC$2:$AC$1031),"") | AE2: =IF(ISNUMBER(AF2),AF2/3630,"") | AF2: =IFERROR(C2+D2+E2+F2+J2+K2+L2+M2+Q2+R2+S2+T2+IF(ISNUMBER(X2),X2,0)+N(Y2)+N(Z2)+N(AA2),"") | AG2: =IF(ISNUMBER(AF2),AF2,"") | AH2: =IF(ISNUMBER(AG2),_xlfn.RANK.EQ(AG2,$AG$2:$AG$1031),"")
A3: 6 | B3: ابراهيم احمد جابر سلام | C3: 601.8 | D3: 23 | E3: 21 | F3: 20 | G3: =C3+D3+E3+F3 | H3: =IF(ISNUMBER(G3),G3,"") | I3: =_xlfn.RANK.EQ(H3,$H$2:$H$1031) | J3: 552.7 | K3: 37 | L3: 21 | M3: 15 | N3: =J3+K3+L3+M3 | O3: =IF(ISNUMBER(N3),N3,"") | P3: =_xlfn.RANK.EQ(O3,$O$2:$O$1031) | Q3: 219.5 | R3: 42.5 | S3: 21 | T3: 24 | U3: =Q3+R3+S3+T3 | V3: =IF(ISNUMBER(U3),U3,"") | W3: =_xlfn.RANK.EQ(V3,$V$2:$V$1031) | X3: 1341.8125 | Y3: 23 | Z3: 22 | AA3: 17 | AB3: =IF(ISNUMBER(X3),X3+N(Y3)+N(Z3)+N(AA3),X3) | AC3: =IF(ISNUMBER(AB3),AB3,"") | AD3: =IF(ISNUMBER(AC3),_xlfn.RANK.EQ(AC3,$AC$2:$AC$1031),"") | AE3: =IF(ISNUMBER(AF3),AF3/3630,"") | AF3: =IFERROR(C3+D3+E3+F3+J3+K3+L3+M3+Q3+R3+S3+T3+IF(ISNUMBER(X3),X3,0)+N(Y3)+N(Z3)+N(AA3),"") | AG3: =IF(ISNUMBER(AF3),AF3,"") | AH3: =IF(ISNUMBER(AG3),_xlfn.RANK.EQ(AG3,$AG$2:$AG$1031),"")
A4: 9 | B4: ابراهيم حسنى محمد على حسونه | C4: 654 | D4: 25 | E4: 25 | F4: 23 | G4: =C4+D4+E4+F4 | H4: =IF(ISNUMBER(G4),G4,"") | I4: =_xlfn.RANK.EQ(H4,$H$2:$H$1031) | J4: 635.5 | K4: 48 | L4: 19 | M4: 23 | N4: =J4+K4+L4+M4 | O4: =IF(ISNUMBER(N4),N4,"") | P4: =_xlfn.RANK.EQ(O4,$O$2:$O$1031) | Q4: 289 | R4: 48.5 | S4: 23 | T4: 25 | U4: =Q4+R4+S4+T4 | V4: =IF(ISNUMBER(U4),U4,"") | W4: =_xlfn.RANK.EQ(V4,$V$2:$V$1031) | X4: 1585.8333 | Y4: 25 | Z4: 25 | AA4: 23 | AB4: =IF(ISNUMBER(X4),X4+N(Y4)+N(Z4)+N(AA4),X4) | AC4: =IF(ISNUMBER(AB4),AB4,"") | AD4: =IF(ISNUMBER(AC4),_xlfn.RANK.EQ(AC4,$AC$2:$AC$1031),"") | AE4: =IF(ISNUMBER(AF4),AF4/3630,"") | AF4: =IFERROR(C4+D4+E4+F4+J4+K4+L4+M4+Q4+R4+S4+T4+IF(ISNUMBER(X4),X4,0)+N(Y4)+N(Z4)+N(AA4),"") | AG4: =IF(ISNUMBER(AF4),AF4,"") | AH4: =IF(ISNUMBER(AG4),_xlfn.RANK.EQ(AG4,$AG$2:$AG$1031),"")
A5: 13 | B5: ابراهيم علاء مرزوق على اغا | C5: 440 | D5: 23 | E5: 6 | F5: 18 | G5: =C5+D5+E5+F5 | H5: =IF(ISNUMBER(G5),G5,"") | I5: =_xlfn.RANK.EQ(H5,$H$2:$H$1031) | J5: 407.5 | K5: 23 | L5: 13 | M5: 11 | N5: =J5+K5+L5+M5 | O5: =IF(ISNUMBER(N5),N5,"") | P5: =_xlfn.RANK.EQ(O5,$O$2:$O$1031) | Q5: 152.75 | R5: 34 | S5: 22 | T5: 22 | U5: =Q5+R5+S5+T5 | V5: =IF(ISNUMBER(U5),U5,"") | W5: =_xlfn.RANK.EQ(V5,$V$2:$V$1031) | X5: 1150.8042 | Y5: 25 | Z5: 21 | AA5: 20 | AB5: =IF(ISNUMBER(X5),X5+N(Y5)+N(Z5)+N(AA5),X5) | AC5: =IF(ISNUMBER(AB5),AB5,"") | AD5: =IF(ISNUMBER(AC5),_xlfn.RANK.EQ(AC5,$AC$2:$AC$1031),"") | AE5: =IF(ISNUMBER(AF5),AF5/3630,"") | AF5: =IFERROR(C5+D5+E5+F5+J5+K5+L5+M5+Q5+R5+S5+T5+IF(ISNUMBER(X5),X5,0)+N(Y5)+N(Z5)+N(AA5),"") | AG5: =IF(ISNUMBER(AF5),AF5,"") | AH5: =IF(ISNUMBER(AG5),_xlfn.RANK.EQ(AG5,$AG$2:$AG$1031),"")
A6: 15 | B6: ابراهيم محمد حسن عويضه | C6: 565.6 | D6: 24 | E6: 22 | F6: 18 | G6: =C6+D6+E6+F6 | H6: =IF(ISNUMBER(G6),G6,"") | I6: =_xlfn.RANK.EQ(H6,$H$2:$H$1031) | J6: 599.5 | K6: 49 | L6: 25 | M6: 22 | N6: =J6+K6+L6+M6 | O6: =IF(ISNUMBER(N6),N6,"") | P6: =_xlfn.RANK.EQ(O6,$O$2:$O$1031) | Q6: 243 | R6: 43 | S6: 22 | T6: 25 | U6: =Q6+R6+S6+T6 | V6: =IF(ISNUMBER(U6),U6,"") | W6: =_xlfn.RANK.EQ(V6,$V$2:$V$1031) | X6: 1403.6083 | Y6: 25 | Z6: 23 | AA6: 22 | AB6: =IF(ISNUMBER(X6),X6+N(Y6)+N(Z6)+N(AA6),X6) | AC6: =IF(ISNUMBER(AB6),AB6,"") | AD6: =IF(ISNUMBER(AC6),_xlfn.RANK.EQ(AC6,$AC$2:$AC$1031),"") | AE6: =IF(ISNUMBER(AF6),AF6/3630,"") | AF6: =IFERROR(C6+D6+E6+F6+J6+K6+L6+M6+Q6+R6+S6+T6+IF(ISNUMBER(X6),X6,0)+N(Y6)+N(Z6)+N(AA6),"") | AG6: =IF(ISNUMBER(AF6),AF6,"") | AH6: =IF(ISNUMBER(AG6),_xlfn.RANK.EQ(AG6,$AG$2:$AG$1031),"")
A7: 31 | B7: احلام محمد خميس على عبدالكريم | C7: 616.7 | D7: 25 | E7: 24 | F7: 23 | G7: =C7+D7+E7+F7 | H7: =IF(ISNUMBER(G7),G7,"") | I7: =_xlfn.RANK.EQ(H7,$H$2:$H$1031) | J7: 629.4 | K7: 46 | L7: 21 | M7: 22 | N7: =J7+K7+L7+M7 | O7: =IF(ISNUMBER(N7),N7,"") | P7: =_xlfn.RANK.EQ(O7,$O$2:$O$1031) | Q7: 272 | R7: 48 | S7: 24 | T7: 25 | U7: =Q7+R7+S7+T7 | V7: =IF(ISNUMBER(U7),U7,"") | W7: =_xlfn.RANK.EQ(V7,$V$2:$V$1031) | X7: 1497.6708 | Y7: 25 | Z7: 25 | AA7: 24 | AB7: =IF(ISNUMBER(X7),X7+N(Y7)+N(Z7)+N(AA7),X7) | AC7: =IF(ISNUMBER(AB7),AB7,"") | AD7: =IF(ISNUMBER(AC7),_xlfn.RANK.EQ(AC7,$AC$2:$AC$1031),"") | AE7: =IF(ISNUMBER(AF7),AF7/3630,"") | AF7: =IFERROR(C7+D7+E7+F7+J7+K7+L7+M7+Q7+R7+S7+T7+IF(ISNUMBER(X7),X7,0)+N(Y7)+N(Z7)+N(AA7),"") | AG7: =IF(ISNUMBER(AF7),AF7,"") | AH7: =IF(ISNUMBER(AG7),_xlfn.RANK.EQ(AG7,$AG$2:$AG$1031),"")
A8: 32 | B8: احمد ابراهيم ابراهيم سيد احمد عيسى | C8: 598.8 | D8: 24 | E8: 22 | F8: 24 | G8: =C8+D8+E8+F8 | H8: =IF(ISNUMBER(G8),G8,"") | I8: =_xlfn.RANK.EQ(H8,$H$2:$H$1031) | J8: 589.8 | K8: 49 | L8: 22 | M8: 25 | N8: =J8+K8+L8+M8 | O8: =IF(ISNUMBER(N8),N8,"") | P8: =_xlfn.RANK.EQ(O8,$O$2:$O$1031) | Q8: 272 | R8: 47.5 | S8: 24 | T8: 25 | U8: =Q8+R8+S8+T8 | V8: =IF(ISNUMBER(U8),U8,"") | W8: =_xlfn.RANK.EQ(V8,$V$2:$V$1031) | X8: 1369.3833 | Y8: 24 | Z8: 24 | AA8: 22 | AB8: =IF(ISNUMBER(X8),X8+N(Y8)+N(Z8)+N(AA8),X8) | AC8: =IF(ISNUMBER(AB8),AB8,"") | AD8: =IF(ISNUMBER(AC8),_xlfn.RANK.EQ(AC8,$AC$2:$AC$1031),"") | AE8: =IF(ISNUMBER(AF8),AF8/3630,"") | AF8: =IFERROR(C8+D8+E8+F8+J8+K8+L8+M8+Q8+R8+S8+T8+IF(ISNUMBER(X8),X8,0)+N(Y8)+N(Z8)+N(AA8),"") | AG8: =IF(ISNUMBER(AF8),AF8,"") | AH8: =IF(ISNUMBER(AG8),_xlfn.RANK.EQ(AG8,$AG$2:$AG$1031),"")
A9: 34 | B9: احمد ابراهيم فاروق سعد الششتاوى | C9: 477 | D9: 24 | E9: 22 | F9: 24 | G9: =C9+D9+E9+F9 | H9: =IF(ISNUMBER(G9),G9,"") | I9: =_xlfn.RANK.EQ(H9,$H$2:$H$1031) | J9: 545.3 | K9: 49 | L9: 22 | M9: 23 | N9: =J9+K9+L9+M9 | O9: =IF(ISNUMBER(N9),N9,"") | P9: =_xlfn.RANK.EQ(O9,$O$2:$O$1031) | Q9: 226.5 | R9: 31.5 | S9: 16 | T9: 23 | U9: =Q9+R9+S9+T9 | V9: =IF(ISNUMBER(U9),U9,"") | W9: =_xlfn.RANK.EQ(V9,$V$2:$V$1031) | X9: 1191.0458 | Y9: 25 | Z9: 18 | AA9: 22 | AB9: =IF(ISNUMBER(X9),X9+N(Y9)+N(Z9)+N(AA9),X9) | AC9: =IF(ISNUMBER(AB9),AB9,"") | AD9: =IF(ISNUMBER(AC9),_xlfn.RANK.EQ(AC9,$AC$2:$AC$1031),"") | AE9: =IF(ISNUMBER(AF9),AF9/3630,"") | AF9: =IFERROR(C9+D9+E9+F9+J9+K9+L9+M9+Q9+R9+S9+T9+IF(ISNUMBER(X9),X9,0)+N(Y9)+N(Z9)+N(AA9),"") | AG9: =IF(ISNUMBER(AF9),AF9,"") | AH9: =IF(ISNUMBER(AG9),_xlfn.RANK.EQ(AG9,$AG$2:$AG$1031),"")
A10: 35 | B10: احمد احمد ابراهيم احمد عويضه | C10: 515.2 | D10: 21 | E10: 25 | F10: 20.5 | G10: =C10+D10+E10+F10 | H10: =IF(ISNUMBER(G10),G10,"") | I10: =_xlfn.RANK.EQ(H10,$H$2:$H$1031) | J10: 551 | K10: 46 | L10: 22 | M10: 23 | N10: =J10+K10+L10+M10 | O10: =IF(ISNUMBER(N10),N10,"") | P10: =_xlfn.RANK.EQ(O10,$O$2:$O$1031) | Q10: 264 | R10: 45 | S10: 22 | T10: 23.5 | U10: =Q10+R10+S10+T10 | V10: =IF(ISNUMBER(U10),U10,"") | W10: =_xlfn.RANK.EQ(V10,$V$2:$V$1031) | X10: 1386.7375 | Y10: 25 | Z10: 21 | AA10: 20 | AB10: =IF(ISNUMBER(X10),X10+N(Y10)+N(Z10)+N(AA10),X10) | AC10: =IF(ISNUMBER(AB10),AB10,"") | AD10: =IF(ISNUMBER(AC10),_xlfn.RANK.EQ(AC10,$AC$2:$AC$1031),"") | AE10: =IF(ISNUMBER(AF10),AF10/3630,"") | AF10: =IFERROR(C10+D10+E10+F10+J10+K10+L10+M10+Q10+R10+S10+T10+IF(ISNUMBER(X10),X10,0)+N(Y10)+N(Z10)+N(AA10),"") | AG10: =IF(ISNUMBER(AF10),AF10,"") | AH10: =IF(ISNUMBER(AG10),_xlfn.RANK.EQ(AG10,$AG$2:$AG$1031),"")
A11: 37 | B11: احمد اشرف عبد الزين عباس | C11: 658 | D11: 25 | E11: 25 | F11: 24 | G11: =C11+D11+E11+F11 | H11: =IF(ISNUMBER(G11),G11,"") | I11: =_xlfn.RANK.EQ(H11,$H$2:$H$1031) | J11: 633.7 | K11: 47 | L11: 23 | M11: 23 | N11: =J11+K11+L11+M11 | O11: =IF(ISNUMBER(N11),N11,"") | P11: =_xlfn.RANK.EQ(O11,$O$2:$O$1031) | Q11: 283 | R11: 47 | S11: 22 | T11: 24.5 | U11: =Q11+R11+S11+T11 | V11: =IF(ISNUMBER(U11),U11,"") | W11: =_xlfn.RANK.EQ(V11,$V$2:$V$1031) | X11: 1528.7583 | Y11: 25 | Z11: 20 | AA11: 21 | AB11: =IF(ISNUMBER(X11),X11+N(Y11)+N(Z11)+N(AA11),X11) | AC11: =IF(ISNUMBER(AB11),AB11,"") | AD11: =IF(ISNUMBER(AC11),_xlfn.RANK.EQ(AC11,$AC$2:$AC$1031),"") | AE11: =IF(ISNUMBER(AF11),AF11/3630,"") | AF11: =IFERROR(C11+D11+E11+F11+J11+K11+L11+M11+Q11+R11+S11+T11+IF(ISNUMBER(X11),X11,0)+N(Y11)+N(Z11)+N(AA11),"") | AG11: =IF(ISNUMBER(AF11),AF11,"") | AH11: =IF(ISNUMBER(AG11),_xlfn.RANK.EQ(AG11,$AG$2:$AG$1031),"")
A12: 38 | B12: احمد اشرف عبد الفتاح عبد ربه | C12: 472.1 | D12: 19 | E12: 20 | F12: 16 | G12: =C12+D12+E12+F12 | H12: =IF(ISNUMBER(G12),G12,"") | I12: =_xlfn.RANK.EQ(H12,$H$2:$H$1031) | J12: 510.7 | K12: 34 | L12: 20 | M12: 18 | N12: =J12+K12+L12+M12 | O12: =IF(ISNUMBER(N12),N12,"") | P12: =_xlfn.RANK.EQ(O12,$O$2:$O$1031) | Q12: 212.5 | R12: 43 | S12: 25 | T12: 22.5 | U12: =Q12+R12+S12+T12 | V12: =IF(ISNUMBER(U12),U12,"") | W12: =_xlfn.RANK.EQ(V12,$V$2:$V$1031) | X12: 1292.6167 | Y12: 25 | Z12: 22 | AA12: 25 | AB12: =IF(ISNUMBER(X12),X12+N(Y12)+N(Z12)+N(AA12),X12) | AC12: =IF(ISNUMBER(AB12),AB12,"") | AD12: =IF(ISNUMBER(AC12),_xlfn.RANK.EQ(AC12,$AC$2:$AC$1031),"") | AE12: =IF(ISNUMBER(AF12),AF12/3630,"") | AF12: =IFERROR(C12+D12+E12+F12+J12+K12+L12+M12+Q12+R12+S12+T12+IF(ISNUMBER(X12),X12,0)+N(Y12)+N(Z12)+N(AA12),"") | AG12: =IF(ISNUMBER(AF12),AF12,"") | AH12: =IF(ISNUMBER(AG12),_xlfn.RANK.EQ(AG12,$AG$2:$AG$1031),"")
A13: 39 | B13: احمد اشرف عطية محمود القزاز | C13: 639.5 | D13: 25 | E13: 25 | F13: 22 | G13: =C13+D13+E13+F13 | H13: =IF(ISNUMBER(G13),G13,"") | I13: =_xlfn.RANK.EQ(H13,$H$2:$H$1031) | J13: 622.7 | K13: 49 | L13: 22 | M13: 23 | N13: =J13+K13+L13+M13 | O13: =IF(ISNUMBER(N13),N13,"") | P13: =_xlfn.RANK.EQ(O13,$O$2:$O$1031) | Q13: 274.5 | R13: 48 | S13: 24 | T13: 24.5 | U13: =Q13+R13+S13+T13 | V13: =IF(ISNUMBER(U13),U13,"") | W13: =_xlfn.RANK.EQ(V13,$V$2:$V$1031) | X13: 1395.3208 | Y13: 25 | Z13: 22 | AA13: 23 | AB13: =IF(ISNUMBER(X13),X13+N(Y13)+N(Z13)+N(AA13),X13) | AC13: =IF(ISNUMBER(AB13),AB13,"") | AD13: =IF(ISNUMBER(AC13),_xlfn.RANK.EQ(AC13,$AC$2:$AC$1031),"") | AE13: =IF(ISNUMBER(AF13),AF13/3630,"") | AF13: =IFERROR(C13+D13+E13+F13+J13+K13+L13+M13+Q13+R13+S13+T13+IF(ISNUMBER(X13),X13,0)+N(Y13)+N(Z13)+N(AA13),"") | AG13: =IF(ISNUMBER(AF13),AF13,"") | AH13: =IF(ISNUMBER(AG13),_xlfn.RANK.EQ(AG13,$AG$2:$AG$1031),"")
A14: 40 | B14: احمد اشرف محمد شريف | C14: 607.9 | D14: 24 | E14: 25 | F14: 21 | G14: =C14+D14+E14+F14 | H14: =IF(ISNUMBER(G14),G14,"") | I14: =_xlfn.RANK.EQ(H14,$H$2:$H$1031) | J14: 543.7 | K14: 39 | L14: 20 | M14: 21 | N14: =J14+K14+L14+M14 | O14: =IF(ISNUMBER(N14),N14,"") | P14: =_xlfn.RANK.EQ(O14,$O$2:$O$1031) | Q14: 231.5 | R14: 44.5 | S14: 24 | T14: 25 | U14: =Q14+R14+S14+T14 | V14: =IF(ISNUMBER(U14),U14,"") | W14: =_xlfn.RANK.EQ(V14,$V$2:$V$1031) | X14: راسب | Y14: 25 | Z14: 21 | AA14: 22 | AB14: =IF(ISNUMBER(X14),X14+N(Y14)+N(Z14)+N(AA14),X14) | AC14: =IF(ISNUMBER(AB14),AB14,"") | AD14: =IF(ISNUMBER(AC14),_xlfn.RANK.EQ(AC14,$AC$2:$AC$1031),"") | AE14: =IF(ISNUMBER(AF14),AF14/3630,"") | AF14: =IFERROR(C14+D14+E14+F14+J14+K14+L14+M14+Q14+R14+S14+T14+IF(ISNUMBER(X14),X14,0)+N(Y14)+N(Z14)+N(AA14),"") | AG14: =IF(ISNUMBER(AF14),AF14,"") | AH14: =IF(ISNUMBER(AG14),_xlfn.RANK.EQ(AG14,$AG$2:$AG$1031),"")
A15: 41 | B15: احمد اشرف محمود محمد | C15: 579.3 | D15: 22 | E15: 25 | F15: 23 | G15: =C15+D15+E15+F15 | H15: =IF(ISNUMBER(G15),G15,"") | I15: =_xlfn.RANK.EQ(H15,$H$2:$H$1031) | J15: 587.5 | K15: 49 | L15: 23 | M15: 22 | N15: =J15+K15+L15+M15 | O15: =IF(ISNUMBER(N15),N15,"") | P15: =_xlfn.RANK.EQ(O15,$O$2:$O$1031) | Q15: 271 | R15: 46.5 | S15: 23 | T15: 25 | U15: =Q15+R15+S15+T15 | V15: =IF(ISNUMBER(U15),U15,"") | W15: =_xlfn.RANK.EQ(V15,$V$2:$V$1031) | X15: 1454.7958 | Y15: 21 | Z15: 21 | AA15: 22 | AB15: =IF(ISNUMBER(X15),X15+N(Y15)+N(Z15)+N(AA15),X15) | AC15: =IF(ISNUMBER(AB15),AB15,"") | AD15: =IF(ISNUMBER(AC15),_xlfn.RANK.EQ(AC15,$AC$2:$AC$1031),"") | AE15: =IF(ISNUMBER(AF15),AF15/3630,"") | AF15: =IFERROR(C15+D15+E15+F15+J15+K15+L15+M15+Q15+R15+S15+T15+IF(ISNUMBER(X15),X15,0)+N(Y15)+N(Z15)+N(AA15),"") | AG15: =IF(ISNUMBER(AF15),AF15,"") | AH15: =IF(ISNUMBER(AG15),_xlfn.RANK.EQ(AG15,$AG$2:$AG$1031),"")
A16: 42 | B16: احمد السعيد عطيه المليجى | C16: 581.7 | D16: 24 | E16: 21 | F16: 21 | G16: =C16+D16+E16+F16 | H16: =IF(ISNUMBER(G16),G16,"") | I16: =_xlfn.RANK.EQ(H16,$H$2:$H$1031) | J16: 534.9 | K16: 44 | L16: 25 | M16: 17 | N16: =J16+K16+L16+M16 | O16: =IF(ISNUMBER(N16),N16,"") | P16: =_xlfn.RANK.EQ(O16,$O$2:$O$1031) | Q16: 239 | R16: 41.5 | S16: 24 | T16: 23 | U16: =Q16+R16+S16+T16 | V16: =IF(ISNUMBER(U16),U16,"") | W16: =_xlfn.RANK.EQ(V16,$V$2:$V$1031) | X16: 1333.0958 | Y16: 25 | Z16: 17 | AA16: 24 | AB16: =IF(ISNUMBER(X16),X16+N(Y16)+N(Z16)+N(AA16),X16) | AC16: =IF(ISNUMBER(AB16),AB16,"") | AD16: =IF(ISNUMBER(AC16),_xlfn.RANK.EQ(AC16,$AC$2:$AC$1031),"") | AE16: =IF(ISNUMBER(AF16),AF16/3630,"") | AF16: =IFERROR(C16+D16+E16+F16+J16+K16+L16+M16+Q16+R16+S16+T16+IF(ISNUMBER(X16),X16,0)+N(Y16)+N(Z16)+N(AA16),"") | AG16: =IF(ISNUMBER(AF16),AF16,"") | AH16: =IF(ISNUMBER(AG16),_xlfn.RANK.EQ(AG16,$AG$2:$AG$1031),"")
A17: 46 | B17: احمد ايهاب حسن جابر | C17: 489.6 | D17: 18 | E17: 20 | F17: 20 | G17: =C17+D17+E17+F17 | H17: =IF(ISNUMBER(G17),G17,"") | I17: =_xlfn.RANK.EQ(H17,$H$2:$H$1031) | J17: 557.2 | K17: 36 | L17: 20 | M17: 17 | N17: =J17+K17+L17+M17 | O17: =IF(ISNUMBER(N17),N17,"") | P17: =_xlfn.RANK.EQ(O17,$O$2:$O$1031) | Q17: 216.5 | R17: 42 | S17: 21 | T17: 23 | U17: =Q17+R17+S17+T17 | V17: =IF(ISNUMBER(U17),U17,"") | W17: =_xlfn.RANK.EQ(V17,$V$2:$V$1031) | X17: 1315.0417 | Y17: 22 | Z17: 25 | AA17: 22 | AB17: =IF(ISNUMBER(X17),X17+N(Y17)+N(Z17)+N(AA17),X17) | AC17: =IF(ISNUMBER(AB17),AB17,"") | AD17: =IF(ISNUMBER(AC17),_xlfn.RANK.EQ(AC17,$AC$2:$AC$1031),"") | AE17: =IF(ISNUMBER(AF17),AF17/3630,"") | AF17: =IFERROR(C17+D17+E17+F17+J17+K17+L17+M17+Q17+R17+S17+T17+IF(ISNUMBER(X17),X17,0)+N(Y17)+N(Z17)+N(AA17),"") | AG17: =IF(ISNUMBER(AF17),AF17,"") | AH17: =IF(ISNUMBER(AG17),_xlfn.RANK.EQ(AG17,$AG$2:$AG$1031),"")
A18: 50 | B18: احمد جميل عبد الحليم فرج محمد | C18: 590 | D18: 24 | E18: 25 | F18: 23 | G18: =C18+D18+E18+F18 | H18: =IF(ISNUMBER(G18),G18,"") | I18: =_xlfn.RANK.EQ(H18,$H$2:$H$1031) | J18: 574.7 | K18: 49 | L18: 20 | M18: 20 | N18: =J18+K18+L18+M18 | O18: =IF(ISNUMBER(N18),N18,"") | P18: =_xlfn.RANK.EQ(O18,$O$2:$O$1031) | Q18: 230.5 | R18: 45 | S18: 21 | T18: 22.5 | U18: =Q18+R18+S18+T18 | V18: =IF(ISNUMBER(U18),U18,"") | W18: =_xlfn.RANK.EQ(V18,$V$2:$V$1031) | X18: 1265.0208 | Y18: 25 | Z18: 25 | AA18: 24 | AB18: =IF(ISNUMBER(X18),X18+N(Y18)+N(Z18)+N(AA18),X18) | AC18: =IF(ISNUMBER(AB18),AB18,"") | AD18: =IF(ISNUMBER(AC18),_xlfn.RANK.EQ(AC18,$AC$2:$AC$1031),"") | AE18: =IF(ISNUMBER(AF18),AF18/3630,"") | AF18: =IFERROR(C18+D18+E18+F18+J18+K18+L18+M18+Q18+R18+S18+T18+IF(ISNUMBER(X18),X18,0)+N(Y18)+N(Z18)+N(AA18),"") | AG18: =IF(ISNUMBER(AF18),AF18,"") | AH18: =IF(ISNUMBER(AG18),_xlfn.RANK.EQ(AG18,$AG$2:$AG$1031),"")
A19: 51 | B19: احمد حسام الدين فتحى ابوالخير | C19: 494.2 | D19: 18 | E19: 20 | F19: 21 | G19: =C19+D19+E19+F19 | H19: =IF(ISNUMBER(G19),G19,"") | I19: =_xlfn.RANK.EQ(H19,$H$2:$H$1031) | J19: 460.7 | K19: 39 | L19: 18 | M19: 18 | N19: =J19+K19+L19+M19 | O19: =IF(ISNUMBER(N19),N19,"") | P19: =_xlfn.RANK.EQ(O19,$O$2:$O$1031) | Q19: 216 | R19: 39 | S19: 22 | T19: 25 | U19: =Q19+R19+S19+T19 | V19: =IF(ISNUMBER(U19),U19,"") | W19: =_xlfn.RANK.EQ(V19,$V$2:$V$1031) | X19: 1298.6708 | Y19: 22 | Z19: 24 | AA19: 20 | AB19: =IF(ISNUMBER(X19),X19+N(Y19)+N(Z19)+N(AA19),X19) | AC19: =IF(ISNUMBER(AB19),AB19,"") | AD19: =IF(ISNUMBER(AC19),_xlfn.RANK.EQ(AC19,$AC$2:$AC$1031),"") | AE19: =IF(ISNUMBER(AF19),AF19/3630,"") | AF19: =IFERROR(C19+D19+E19+F19+J19+K19+L19+M19+Q19+R19+S19+T19+IF(ISNUMBER(X19),X19,0)+N(Y19)+N(Z19)+N(AA19),"") | AG19: =IF(ISNUMBER(AF19),AF19,"") | AH19: =IF(ISNUMBER(AG19),_xlfn.RANK.EQ(AG19,$AG$2:$AG$1031),"")
A20: 52 | B20: احمد حسام عبد المجيد علي | C20: 555.6 | D20: 24 | E20: 22 | F20: 16.5 | G20: =C20+D20+E20+F20 | H20: =IF(ISNUMBER(G20),G20,"") | I20: =_xlfn.RANK.EQ(H20,$H$2:$H$1031) | J20: 490.4 | K20: 30 | L20: 16 | M20: 14 | N20: =J20+K20+L20+M20 | O20: =IF(ISNUMBER(N20),N20,"") | P20: =_xlfn.RANK.EQ(O20,$O$2:$O$1031) | Q20: 206 | R20: 41.5 | S20: 22 | T20: 23.5 | U20: =Q20+R20+S20+T20 | V20: =IF(ISNUMBER(U20),U20,"") | W20: =_xlfn.RANK.EQ(V20,$V$2:$V$1031) | X20: راسب | Y20: 23 | Z20: 24 | AA20: 21 | AB20: =IF(ISNUMBER(X20),X20+N(Y20)+N(Z20)+N(AA20),X20) | AC20: =IF(ISNUMBER(AB20),AB20,"") | AD20: =IF(ISNUMBER(AC20),_xlfn.RANK.EQ(AC20,$AC$2:$AC$1031),"") | AE20: =IF(ISNUMBER(AF20),AF20/3630,"") | AF20: =IFERROR(C20+D20+E20+F20+J20+K20+L20+M20+Q20+R20+S20+T20+IF(ISNUMBER(X20),X20,0)+N(Y20)+N(Z20)+N(AA20),"") | AG20: =IF(ISNUMBER(AF20),AF20,"") | AH20: =IF(ISNUMBER(AG20),_xlfn.RANK.EQ(AG20,$AG$2:$AG$1031),"")
A21: 53 | B21: احمد حسن ابراهيم المهدى هاشم | C21: 457.1 | D21: 21 | E21: 13 | F21: 21 | G21: =C21+D21+E21+F21 | H21: =IF(ISNUMBER(G21),G21,"") | I21: =_xlfn.RANK.EQ(H21,$H$2:$H$1031) | J21: 457.5 | K21: 37 | L21: 20 | M21: 15 | N21: =J21+K21+L21+M21 | O21: =IF(ISNUMBER(N21),N21,"") | P21: =_xlfn.RANK.EQ(O21,$O$2:$O$1031) | Q21: راسب | R21: 40 | S21: 23 | T21: 19.5 | U21: =Q21+R21+S21+T21 | V21: =IF(ISNUMBER(U21),U21,"") | W21: =_xlfn.RANK.EQ(V21,$V$2:$V$1031) | X21: راسب | Y21: 23 | Z21: 25 | AA21: 20 | AB21: =IF(ISNUMBER(X21),X21+N(Y21)+N(Z21)+N(AA21),X21) | AC21: =IF(ISNUMBER(AB21),AB21,"") | AD21: =IF(ISNUMBER(AC21),_xlfn.RANK.EQ(AC21,$AC$2:$AC$1031),"") | AE21: =IF(ISNUMBER(AF21),AF21/3630,"") | AF21: =IFERROR(C21+D21+E21+F21+J21+K21+L21+M21+Q21+R21+S21+T21+IF(ISNUMBER(X21),X21,0)+N(Y21)+N(Z21)+N(AA21),"") | AG21: =IF(ISNUMBER(AF21),AF21,"") | AH21: =IF(ISNUMBER(AG21),_xlfn.RANK.EQ(AG21,$AG$2:$AG$1031),"")
A22: 54 | B22: احمد حسن أحمد محمد على | C22: 606.2 | D22: 24 | E22: 20 | F22: 22 | G22: =C22+D22+E22+F22 | H22: =IF(ISNUMBER(G22),G22,"") | I22: =_xlfn.RANK.EQ(H22,$H$2:$H$1031) | J22: 615 | K22: 49 | L22: 22 | M22: 21 | N22: =J22+K22+L22+M22 | O22: =IF(ISNUMBER(N22),N22,"") | P22: =_xlfn.RANK.EQ(O22,$O$2:$O$1031) | Q22: 262 | R22: 47.5 | S22: 25 | T22: 23.5 | U22: =Q22+R22+S22+T22 | V22: =IF(ISNUMBER(U22),U22,"") | W22: =_xlfn.RANK.EQ(V22,$V$2:$V$1031) | X22: 1492.9292 | Y22: 24 | Z22: 23 | AA22: 22 | AB22: =IF(ISNUMBER(X22),X22+N(Y22)+N(Z22)+N(AA22),X22) | AC22: =IF(ISNUMBER(AB22),AB22,"") | AD22: =IF(ISNUMBER(AC22),_xlfn.RANK.EQ(AC22,$AC$2:$AC$1031),"") | AE22: =IF(ISNUMBER(AF22),AF22/3630,"") | AF22: =IFERROR(C22+D22+E22+F22+J22+K22+L22+M22+Q22+R22+S22+T22+IF(ISNUMBER(X22),X22,0)+N(Y22)+N(Z22)+N(AA22),"") | AG22: =IF(ISNUMBER(AF22),AF22,"") | AH22: =IF(ISNUMBER(AG22),_xlfn.RANK.EQ(AG22,$AG$2:$AG$1031),"")
A23: 55 | B23: احمد حسين محمد محمد البصال | C23: 642.7 | D23: 25 | E23: 24 | F23: 24 | G23: =C23+D23+E23+F23 | H23: =IF(ISNUMBER(G23),G23,"") | I23: =_xlfn.RANK.EQ(H23,$H$2:$H$1031) | J23: 636 | K23: 47 | L23: 24 | M23: 23 | N23: =J23+K23+L23+M23 | O23: =IF(ISNUMBER(N23),N23,"") | P23: =_xlfn.RANK.EQ(O23,$O$2:$O$1031) | Q23: 257 | R23: 45.5 | S23: 23 | T23: 25 | U23: =Q23+R23+S23+T23 | V23: =IF(ISNUMBER(U23),U23,"") | W23: =_xlfn.RANK.EQ(V23,$V$2:$V$1031) | X23: 1451.875 | Y23: 24 | Z23: 20 | AA23: 21 | AB23: =IF(ISNUMBER(X23),X23+N(Y23)+N(Z23)+N(AA23),X23) | AC23: =IF(ISNUMBER(AB23),AB23,"") | AD23: =IF(ISNUMBER(AC23),_xlfn.RANK.EQ(AC23,$AC$2:$AC$1031),"") | AE23: =IF(ISNUMBER(AF23),AF23/3630,"") | AF23: =IFERROR(C23+D23+E23+F23+J23+K23+L23+M23+Q23+R23+S23+T23+IF(ISNUMBER(X23),X23,0)+N(Y23)+N(Z23)+N(AA23),"") | AG23: =IF(ISNUMBER(AF23),AF23,"") | AH23: =IF(ISNUMBER(AG23),_xlfn.RANK.EQ(AG23,$AG$2:$AG$1031),"")
A24: 58 | B24: احمد خالد عبدالغنى عبدالجليل | C24: 499.1 | D24: 18 | E24: 22 | F24: 21 | G24: =C24+D24+E24+F24 | H24: =IF(ISNUMBER(G24),G24,"") | I24: =_xlfn.RANK.EQ(H24,$H$2:$H$1031) | J24: 578.5 | K24: 40 | L24: 24 | M24: 23 | N24: =J24+K24+L24+M24 | O24: =IF(ISNUMBER(N24),N24,"") | P24: =_xlfn.RANK.EQ(O24,$O$2:$O$1031) | Q24: 245 | R24: 44 | S24: 24 | T24: 24 | U24: =Q24+R24+S24+T24 | V24: =IF(ISNUMBER(U24),U24,"") | W24: =_xlfn.RANK.EQ(V24,$V$2:$V$1031) | X24: 1433.4417 | Y24: 24 | Z24: 24 | AA24: 23 | AB24: =IF(ISNUMBER(X24),X24+N(Y24)+N(Z24)+N(AA24),X24) | AC24: =IF(ISNUMBER(AB24),AB24,"") | AD24: =IF(ISNUMBER(AC24),_xlfn.RANK.EQ(AC24,$AC$2:$AC$1031),"") | AE24: =IF(ISNUMBER(AF24),AF24/3630,"") | AF24: =IFERROR(C24+D24+E24+F24+J24+K24+L24+M24+Q24+R24+S24+T24+IF(ISNUMBER(X24),X24,0)+N(Y24)+N(Z24)+N(AA24),"") | AG24: =IF(ISNUMBER(AF24),AF24,"") | AH24: =IF(ISNUMBER(AG24),_xlfn.RANK.EQ(AG24,$AG$2:$AG$1031),"")
A25: 59 | B25: احمد خالد محمد مبروك صقر | C25: 639.7 | D25: 25 | E25: 24 | F25: 23 | G25: =C25+D25+E25+F25 | H25: =IF(ISNUMBER(G25),G25,"") | I25: =_xlfn.RANK.EQ(H25,$H$2:$H$1031) | J25: 613 | K25: 47 | L25: 24 | M25: 23 | N25: =J25+K25+L25+M25 | O25: =IF(ISNUMBER(N25),N25,"") | P25: =_xlfn.RANK.EQ(O25,$O$2:$O$1031) | Q25: 260 | R25: 47.5 | S25: 24 | T25: 25 | U25: =Q25+R25+S25+T25 | V25: =IF(ISNUMBER(U25),U25,"") | W25: =_xlfn.RANK.EQ(V25,$V$2:$V$1031) | X25: 1426.1042 | Y25: 15 | Z25: 23 | AA25: 23 | AB25: =IF(ISNUMBER(X25),X25+N(Y25)+N(Z25)+N(AA25),X25) | AC25: =IF(ISNUMBER(AB25),AB25,"") | AD25: =IF(ISNUMBER(AC25),_xlfn.RANK.EQ(AC25,$AC$2:$AC$1031),"") | AE25: =IF(ISNUMBER(AF25),AF25/3630,"") | AF25: =IFERROR(C25+D25+E25+F25+J25+K25+L25+M25+Q25+R25+S25+T25+IF(ISNUMBER(X25),X25,0)+N(Y25)+N(Z25)+N(AA25),"") | AG25: =IF(ISNUMBER(AF25),AF25,"") | AH25: =IF(ISNUMBER(AG25),_xlfn.RANK.EQ(AG25,$AG$2:$AG$1031),"")
A26: 60 | B26: احمد خميس الحسيني حماد | C26: 495.7 | D26: 14 | E26: 17 | F26: 16 | G26: =C26+D26+E26+F26 | H26: =IF(ISNUMBER(G26),G26,"") | I26: =_xlfn.RANK.EQ(H26,$H$2:$H$1031) | J26: 493 | K26: 48 | L26: 20 | M26: 16 | N26: =J26+K26+L26+M26 | O26: =IF(ISNUMBER(N26),N26,"") | P26: =_xlfn.RANK.EQ(O26,$O$2:$O$1031) | Q26: 223 | R26: 46.5 | S26: 25 | T26: 23.5 | U26: =Q26+R26+S26+T26 | V26: =IF(ISNUMBER(U26),U26,"") | W26: =_xlfn.RANK.EQ(V26,$V$2:$V$1031) | X26: 1214.5042 | Y26: 25 | Z26: 20 | AA26: 18 | AB26: =IF(ISNUMBER(X26),X26+N(Y26)+N(Z26)+N(AA26),X26) | AC26: =IF(ISNUMBER(AB26),AB26,"") | AD26: =IF(ISNUMBER(AC26),_xlfn.RANK.EQ(AC26,$AC$2:$AC$1031),"") | AE26: =IF(ISNUMBER(AF26),AF26/3630,"") | AF26: =IFERROR(C26+D26+E26+F26+J26+K26+L26+M26+Q26+R26+S26+T26+IF(ISNUMBER(X26),X26,0)+N(Y26)+N(Z26)+N(AA26),"") | AG26: =IF(ISNUMBER(AF26),AF26,"") | AH26: =IF(ISNUMBER(AG26),_xlfn.RANK.EQ(AG26,$AG$2:$AG$1031),"")
A27: 67 | B27: احمد سامح عبد الرحمن حبيب | C27: 611.4 | D27: 24 | E27: 24 | F27: 25 | G27: =C27+D27+E27+F27 | H27: =IF(ISNUMBER(G27),G27,"") | I27: =_xlfn.RANK.EQ(H27,$H$2:$H$1031) | J27: 611.5 | K27: 49 | L27: 23 | M27: 23 | N27: =J27+K27+L27+M27 | O27: =IF(ISNUMBER(N27),N27,"") | P27: =_xlfn.RANK.EQ(O27,$O$2:$O$1031) | Q27: 262 | R27: 45.5 | S27: 24 | T27: 24 | U27: =Q27+R27+S27+T27 | V27: =IF(ISNUMBER(U27),U27,"") | W27: =_xlfn.RANK.EQ(V27,$V$2:$V$1031) | X27: 1472.6833 | Y27: 25 | Z27: 25 | AA27: 24 | AB27: =IF(ISNUMBER(X27),X27+N(Y27)+N(Z27)+N(AA27),X27) | AC27: =IF(ISNUMBER(AB27),AB27,"") | AD27: =IF(ISNUMBER(AC27),_xlfn.RANK.EQ(AC27,$AC$2:$AC$1031),"") | AE27: =IF(ISNUMBER(AF27),AF27/3630,"") | AF27: =IFERROR(C27+D27+E27+F27+J27+K27+L27+M27+Q27+R27+S27+T27+IF(ISNUMBER(X27),X27,0)+N(Y27)+N(Z27)+N(AA27),"") | AG27: =IF(ISNUMBER(AF27),AF27,"") | AH27: =IF(ISNUMBER(AG27),_xlfn.RANK.EQ(AG27,$AG$2:$AG$1031),"")
A28: 68 | B28: احمد سامح عرفه حسن القحافى | C28: 529.9 | D28: 24 | E28: 25 | F28: 22 | G28: =C28+D28+E28+F28 | H28: =IF(ISNUMBER(G28),G28,"") | I28: =_xlfn.RANK.EQ(H28,$H$2:$H$1031) | J28: 540.5 | K28: 49 | L28: 20 | M28: 24 | N28: =J28+K28+L28+M28 | O28: =IF(ISNUMBER(N28),N28,"") | P28: =_xlfn.RANK.EQ(O28,$O$2:$O$1031) | Q28: 253 | R28: 45 | S28: 25 | T28: 25 | U28: =Q28+R28+S28+T28 | V28: =IF(ISNUMBER(U28),U28,"") | W28: =_xlfn.RANK.EQ(V28,$V$2:$V$1031) | X28: راسب | Y28: 25 | Z28: 25 | AA28: 24 | AB28: =IF(ISNUMBER(X28),X28+N(Y28)+N(Z28)+N(AA28),X28) | AC28: =IF(ISNUMBER(AB28),AB28,"") | AD28: =IF(ISNUMBER(AC28),_xlfn.RANK.EQ(AC28,$AC$2:$AC$1031),"") | AE28: =IF(ISNUMBER(AF28),AF28/3630,"") | AF28: =IFERROR(C28+D28+E28+F28+J28+K28+L28+M28+Q28+R28+S28+T28+IF(ISNUMBER(X28),X28,0)+N(Y28)+N(Z28)+N(AA28),"") | AG28: =IF(ISNUMBER(AF28),AF28,"") | AH28: =IF(ISNUMBER(AG28),_xlfn.RANK.EQ(AG28,$AG$2:$AG$1031),"")
A29: 72 | B29: احمد سمير السيد علي العيسوي | C29: 601.5 | D29: 25 | E29: 25 | F29: 23 | G29: =C29+D29+E29+F29 | H29: =IF(ISNUMBER(G29),G29,"") | I29: =_xlfn.RANK.EQ(H29,$H$2:$H$1031) | J29: 608.5 | K29: 49 | L29: 22 | M29: 24 | N29: =J29+K29+L29+M29 | O29: =IF(ISNUMBER(N29),N29,"") | P29: =_xlfn.RANK.EQ(O29,$O$2:$O$1031) | Q29: 272.5 | R29: 48 | S29: 25 | T29: 25 | U29: =Q29+R29+S29+T29 | V29: =IF(ISNUMBER(U29),U29,"") | W29: =_xlfn.RANK.EQ(V29,$V$2:$V$1031) | X29: 1360.1792 | Y29: 25 | Z29: 23 | AA29: 24 | AB29: =IF(ISNUMBER(X29),X29+N(Y29)+N(Z29)+N(AA29),X29) | AC29: =IF(ISNUMBER(AB29),AB29,"") | AD29: =IF(ISNUMBER(AC29),_xlfn.RANK.EQ(AC29,$AC$2:$AC$1031),"") | AE29: =IF(ISNUMBER(AF29),AF29/3630,"") | AF29: =IFERROR(C29+D29+E29+F29+J29+K29+L29+M29+Q29+R29+S29+T29+IF(ISNUMBER(X29),X29,0)+N(Y29)+N(Z29)+N(AA29),"") | AG29: =IF(ISNUMBER(AF29),AF29,"") | AH29: =IF(ISNUMBER(AG29),_xlfn.RANK.EQ(AG29,$AG$2:$AG$1031),"")
A30: 74 | B30: احمد شحاتة عبدالعزيز عبدالقادر | C30: 621.5 | D30: 24 | E30: 22 | F30: 22 | G30: =C30+D30+E30+F30 | H30: =IF(ISNUMBER(G30),G30,"") | I30: =_xlfn.RANK.EQ(H30,$H$2:$H$1031) | J30: 619 | K30: 46 | L30: 20 | M30: 25 | N30: =J30+K30+L30+M30 | O30: =IF(ISNUMBER(N30),N30,"") | P30: =_xlfn.RANK.EQ(O30,$O$2:$O$1031) | Q30: 273 | R30: 46 | S30: 22 | T30: 23 | U30: =Q30+R30+S30+T30 | V30: =IF(ISNUMBER(U30),U30,"") | W30: =_xlfn.RANK.EQ(V30,$V$2:$V$1031) | X30: 1508.7958 | Y30: 25 | Z30: 25 | AA30: 21 | AB30: =IF(ISNUMBER(X30),X30+N(Y30)+N(Z30)+N(AA30),X30) | AC30: =IF(ISNUMBER(AB30),AB30,"") | AD30: =IF(ISNUMBER(AC30),_xlfn.RANK.EQ(AC30,$AC$2:$AC$1031),"") | AE30: =IF(ISNUMBER(AF30),AF30/3630,"") | AF30: =IFERROR(C30+D30+E30+F30+J30+K30+L30+M30+Q30+R30+S30+T30+IF(ISNUMBER(X30),X30,0)+N(Y30)+N(Z30)+N(AA30),"") | AG30: =IF(ISNUMBER(AF30),AF30,"") | AH30: =IF(ISNUMBER(AG30),_xlfn.RANK.EQ(AG30,$AG$2:$AG$1031),"")
A31: 75 | B31: احمد شريف فتحي عبدالفتاح | C31: 595.7 | D31: 22 | E31: 25 | F31: 23 | G31: =C31+D31+E31+F31 | H31: =IF(ISNUMBER(G31),G31,"") | I31: =_xlfn.RANK.EQ(H31,$H$2:$H$1031) | J31: 615 | K31: 49 | L31: 21 | M31: 22 | N31: =J31+K31+L31+M31 | O31: =IF(ISNUMBER(N31),N31,"") | P31: =_xlfn.RANK.EQ(O31,$O$2:$O$1031) | Q31: 272 | R31: 46.5 | S31: 24 | T31: 25 | U31: =Q31+R31+S31+T31 | V31: =IF(ISNUMBER(U31),U31,"") | W31: =_xlfn.RANK.EQ(V31,$V$2:$V$1031) | X31: 1507.9667 | Y31: 25 | Z31: 25 | AA31: 23 | AB31: =IF(ISNUMBER(X31),X31+N(Y31)+N(Z31)+N(AA31),X31) | AC31: =IF(ISNUMBER(AB31),AB31,"") | AD31: =IF(ISNUMBER(AC31),_xlfn.RANK.EQ(AC31,$AC$2:$AC$1031),"") | AE31: =IF(ISNUMBER(AF31),AF31/3630,"") | AF31: =IFERROR(C31+D31+E31+F31+J31+K31+L31+M31+Q31+R31+S31+T31+IF(ISNUMBER(X31),X31,0)+N(Y31)+N(Z31)+N(AA31),"") | AG31: =IF(ISNUMBER(AF31),AF31,"") | AH31: =IF(ISNUMBER(AG31),_xlfn.RANK.EQ(AG31,$AG$2:$AG$1031),"")
A32: 76 | B32: احمد صابر السيد السعيد إبراهيم | C32: 598.1 | D32: 23 | E32: 24 | F32: 24 | G32: =C32+D32+E32+F32 | H32: =IF(ISNUMBER(G32),G32,"") | I32: =_xlfn.RANK.EQ(H32,$H$2:$H$1031) | J32: 617 | K32: 50 | L32: 23 | M32: 20 | N32: =J32+K32+L32+M32 | O32: =IF(ISNUMBER(N32),N32,"") | P32: =_xlfn.RANK.EQ(O32,$O$2:$O$1031) | Q32: 261 | R32: 47.5 | S32: 24 | T32: 25 | U32: =Q32+R32+S32+T32 | V32: =IF(ISNUMBER(U32),U32,"") | W32: =_xlfn.RANK.EQ(V32,$V$2:$V$1031) | X32: 1454.8833 | Y32: 24 | Z32: 24 | AA32: 25 | AB32: =IF(ISNUMBER(X32),X32+N(Y32)+N(Z32)+N(AA32),X32) | AC32: =IF(ISNUMBER(AB32),AB32,"") | AD32: =IF(ISNUMBER(AC32),_xlfn.RANK.EQ(AC32,$AC$2:$AC$1031),"") | AE32: =IF(ISNUMBER(AF32),AF32/3630,"") | AF32: =IFERROR(C32+D32+E32+F32+J32+K32+L32+M32+Q32+R32+S32+T32+IF(ISNUMBER(X32),X32,0)+N(Y32)+N(Z32)+N(AA32),"") | AG32: =IF(ISNUMBER(AF32),AF32,"") | AH32: =IF(ISNUMBER(AG32),_xlfn.RANK.EQ(AG32,$AG$2:$AG$1031),"")
A33: 77 | B33: احمد صبحى درويش محمد موسى عشيبة | C33: 525.8 | D33: 23 | E33: 25 | F33: 22 | G33: =C33+D33+E33+F33 | H33: =IF(ISNUMBER(G33),G33,"") | I33: =_xlfn.RANK.EQ(H33,$H$2:$H$1031) | J33: 562.5 | K33: 46 | L33: 21 | M33: 23 | N33: =J33+K33+L33+M33 | O33: =IF(ISNUMBER(N33),N33,"") | P33: =_xlfn.RANK.EQ(O33,$O$2:$O$1031) | Q33: 263.5 | R33: 46.5 | S33: 24 | T33: 25 | U33: =Q33+R33+S33+T33 | V33: =IF(ISNUMBER(U33),U33,"") | W33: =_xlfn.RANK.EQ(V33,$V$2:$V$1031) | X33: 1415.6875 | Y33: 24 | Z33: 24 | AA33: 23 | AB33: =IF(ISNUMBER(X33),X33+N(Y33)+N(Z33)+N(AA33),X33) | AC33: =IF(ISNUMBER(AB33),AB33,"") | AD33: =IF(ISNUMBER(AC33),_xlfn.RANK.EQ(AC33,$AC$2:$AC$1031),"") | AE33: =IF(ISNUMBER(AF33),AF33/3630,"") | AF33: =IFERROR(C33+D33+E33+F33+J33+K33+L33+M33+Q33+R33+S33+T33+IF(ISNUMBER(X33),X33,0)+N(Y33)+N(Z33)+N(AA33),"") | AG33: =IF(ISNUMBER(AF33),AF33,"") | AH33: =IF(ISNUMBER(AG33),_xlfn.RANK.EQ(AG33,$AG$2:$AG$1031),"")
A34: 78 | B34: احمد صبحي محمد ابراهيم | C34: 585.3 | D34: 25 | E34: 24 | F34: 19 | G34: =C34+D34+E34+F34 | H34: =IF(ISNUMBER(G34),G34,"") | I34: =_xlfn.RANK.EQ(H34,$H$2:$H$1031) | J34: 569 | K34: 38 | L34: 18 | M34: 19 | N34: =J34+K34+L34+M34 | O34: =IF(ISNUMBER(N34),N34,"") | P34: =_xlfn.RANK.EQ(O34,$O$2:$O$1031) | Q34: 221.5 | R34: 42.5 | S34: 23 | T34: 24 | U34: =Q34+R34+S34+T34 | V34: =IF(ISNUMBER(U34),U34,"") | W34: =_xlfn.RANK.EQ(V34,$V$2:$V$1031) | X34: 1426.6042 | Y34: 24 | Z34: 24 | AA34: 23 | AB34: =IF(ISNUMBER(X34),X34+N(Y34)+N(Z34)+N(AA34),X34) | AC34: =IF(ISNUMBER(AB34),AB34,"") | AD34: =IF(ISNUMBER(AC34),_xlfn.RANK.EQ(AC34,$AC$2:$AC$1031),"") | AE34: =IF(ISNUMBER(AF34),AF34/3630,"") | AF34: =IFERROR(C34+D34+E34+F34+J34+K34+L34+M34+Q34+R34+S34+T34+IF(ISNUMBER(X34),X34,0)+N(Y34)+N(Z34)+N(AA34),"") | AG34: =IF(ISNUMBER(AF34),AF34,"") | AH34: =IF(ISNUMBER(AG34),_xlfn.RANK.EQ(AG34,$AG$2:$AG$1031),"")
A35: 79 | B35: احمد صفوت عبد القادر عبد الله عوض | C35: 540.7 | D35: 23 | E35: 19 | F35: 17 | G35: =C35+D35+E35+F35 | H35: =IF(ISNUMBER(G35),G35,"") | I35: =_xlfn.RANK.EQ(H35,$H$2:$H$1031) | J35: 524 | K35: 47 | L35: 22 | M35: 17 | N35: =J35+K35+L35+M35 | O35: =IF(ISNUMBER(N35),N35,"") | P35: =_xlfn.RANK.EQ(O35,$O$2:$O$1031) | Q35: 210 | R35: 41 | S35: 20 | T35: 24 | U35: =Q35+R35+S35+T35 | V35: =IF(ISNUMBER(U35),U35,"") | W35: =_xlfn.RANK.EQ(V35,$V$2:$V$1031) | X35: 1222.3833 | Y35: 23 | Z35: 21 | AA35: 21 | AB35: =IF(ISNUMBER(X35),X35+N(Y35)+N(Z35)+N(AA35),X35) | AC35: =IF(ISNUMBER(AB35),AB35,"") | AD35: =IF(ISNUMBER(AC35),_xlfn.RANK.EQ(AC35,$AC$2:$AC$1031),"") | AE35: =IF(ISNUMBER(AF35),AF35/3630,"") | AF35: =IFERROR(C35+D35+E35+F35+J35+K35+L35+M35+Q35+R35+S35+T35+IF(ISNUMBER(X35),X35,0)+N(Y35)+N(Z35)+N(AA35),"") | AG35: =IF(ISNUMBER(AF35),AF35,"") | AH35: =IF(ISNUMBER(AG35),_xlfn.RANK.EQ(AG35,$AG$2:$AG$1031),"")
A36: 80 | B36: احمد طارق السيد عثمان | C36: 632.7 | D36: 23 | E36: 24 | F36: 24 | G36: =C36+D36+E36+F36 | H36: =IF(ISNUMBER(G36),G36,"") | I36: =_xlfn.RANK.EQ(H36,$H$2:$H$1031) | J36: 619 | K36: 46 | L36: 24 | M36: 24 | N36: =J36+K36+L36+M36 | O36: =IF(ISNUMBER(N36),N36,"") | P36: =_xlfn.RANK.EQ(O36,$O$2:$O$1031) | Q36: 279.5 | R36: 47.5 | S36: 25 | T36: 25 | U36: =Q36+R36+S36+T36 | V36: =IF(ISNUMBER(U36),U36,"") | W36: =_xlfn.RANK.EQ(V36,$V$2:$V$1031) | X36: 1501.1708 | Y36: 25 | Z36: 25 | AA36: 23 | AB36: =IF(ISNUMBER(X36),X36+N(Y36)+N(Z36)+N(AA36),X36) | AC36: =IF(ISNUMBER(AB36),AB36,"") | AD36: =IF(ISNUMBER(AC36),_xlfn.RANK.EQ(AC36,$AC$2:$AC$1031),"") | AE36: =IF(ISNUMBER(AF36),AF36/3630,"") | AF36: =IFERROR(C36+D36+E36+F36+J36+K36+L36+M36+Q36+R36+S36+T36+IF(ISNUMBER(X36),X36,0)+N(Y36)+N(Z36)+N(AA36),"") | AG36: =IF(ISNUMBER(AF36),AF36,"") | AH36: =IF(ISNUMBER(AG36),_xlfn.RANK.EQ(AG36,$AG$2:$AG$1031),"")
A37: 81 | B37: احمد طارق امين يونس عبيد | C37: 604.6 | D37: 25 | E37: 23 | F37: 22 | G37: =C37+D37+E37+F37 | H37: =IF(ISNUMBER(G37),G37,"") | I37: =_xlfn.RANK.EQ(H37,$H$2:$H$1031) | J37: 600.5 | K37: 47 | L37: 17 | M37: 20 | N37: =J37+K37+L37+M37 | O37: =IF(ISNUMBER(N37),N37,"") | P37: =_xlfn.RANK.EQ(O37,$O$2:$O$1031) | Q37: 243 | R37: 47.5 | S37: 25 | T37: 24 | U37: =Q37+R37+S37+T37 | V37: =IF(ISNUMBER(U37),U37,"") | W37: =_xlfn.RANK.EQ(V37,$V$2:$V$1031) | X37: 1399.7 | Y37: 25 | Z37: 24 | AA37: 23 | AB37: =IF(ISNUMBER(X37),X37+N(Y37)+N(Z37)+N(AA37),X37) | AC37: =IF(ISNUMBER(AB37),AB37,"") | AD37: =IF(ISNUMBER(AC37),_xlfn.RANK.EQ(AC37,$AC$2:$AC$1031),"") | AE37: =IF(ISNUMBER(AF37),AF37/3630,"") | AF37: =IFERROR(C37+D37+E37+F37+J37+K37+L37+M37+Q37+R37+S37+T37+IF(ISNUMBER(X37),X37,0)+N(Y37)+N(Z37)+N(AA37),"") | AG37: =IF(ISNUMBER(AF37),AF37,"") | AH37: =IF(ISNUMBER(AG37),_xlfn.RANK.EQ(AG37,$AG$2:$AG$1031),"")
A38: 82 | B38: احمد طاهر شعبان خليل | C38: 423.25 | D38: 12 | E38: 13 | F38: 13 | G38: =C38+D38+E38+F38 | H38: =IF(ISNUMBER(G38),G38,"") | I38: =_xlfn.RANK.EQ(H38,$H$2:$H$1031) | J38: 407.5 | K38: 36 | L38: 17 | M38: 24 | N38: =J38+K38+L38+M38 | O38: =IF(ISNUMBER(N38),N38,"") | P38: =_xlfn.RANK.EQ(O38,$O$2:$O$1031) | Q38: 147.5 | R38: 39.5 | S38: 22 | T38: 23 | U38: =Q38+R38+S38+T38 | V38: =IF(ISNUMBER(U38),U38,"") | W38: =_xlfn.RANK.EQ(V38,$V$2:$V$1031) | X38: راسب | Y38: 25 | Z38: 22 | AA38: 17 | AB38: =IF(ISNUMBER(X38),X38+N(Y38)+N(Z38)+N(AA38),X38) | AC38: =IF(ISNUMBER(AB38),AB38,"") | AD38: =IF(ISNUMBER(AC38),_xlfn.RANK.EQ(AC38,$AC$2:$AC$1031),"") | AE38: =IF(ISNUMBER(AF38),AF38/3630,"") | AF38: =IFERROR(C38+D38+E38+F38+J38+K38+L38+M38+Q38+R38+S38+T38+IF(ISNUMBER(X38),X38,0)+N(Y38)+N(Z38)+N(AA38),"") | AG38: =IF(ISNUMBER(AF38),AF38,"") | AH38: =IF(ISNUMBER(AG38),_xlfn.RANK.EQ(AG38,$AG$2:$AG$1031),"")
A39: 83 | B39: احمد عبد الباسط سعد عبد اللطيف | C39: 571.8 | D39: 23 | E39: 19 | F39: 21.5 | G39: =C39+D39+E39+F39 | H39: =IF(ISNUMBER(G39),G39,"") | I39: =_xlfn.RANK.EQ(H39,$H$2:$H$1031) | J39: 578.5 | K39: 46 | L39: 22 | M39: 22 | N39: =J39+K39+L39+M39 | O39: =IF(ISNUMBER(N39),N39,"") | P39: =_xlfn.RANK.EQ(O39,$O$2:$O$1031) | Q39: 252 | R39: 45.5 | S39: 24 | T39: 24.5 | U39: =Q39+R39+S39+T39 | V39: =IF(ISNUMBER(U39),U39,"") | W39: =_xlfn.RANK.EQ(V39,$V$2:$V$1031) | X39: 1389.675 | Y39: 24 | Z39: 24 | AA39: 22 | AB39: =IF(ISNUMBER(X39),X39+N(Y39)+N(Z39)+N(AA39),X39) | AC39: =IF(ISNUMBER(AB39),AB39,"") | AD39: =IF(ISNUMBER(AC39),_xlfn.RANK.EQ(AC39,$AC$2:$AC$1031),"") | AE39: =IF(ISNUMBER(AF39),AF39/3630,"") | AF39: =IFERROR(C39+D39+E39+F39+J39+K39+L39+M39+Q39+R39+S39+T39+IF(ISNUMBER(X39),X39,0)+N(Y39)+N(Z39)+N(AA39),"") | AG39: =IF(ISNUMBER(AF39),AF39,"") | AH39: =IF(ISNUMBER(AG39),_xlfn.RANK.EQ(AG39,$AG$2:$AG$1031),"")
A40: 85 | B40: احمد عبد السلام السعيد الصياد | C40: 593.4 | D40: 22 | E40: 19 | F40: 25 | G40: =C40+D40+E40+F40 | H40: =IF(ISNUMBER(G40),G40,"") | I40: =_xlfn.RANK.EQ(H40,$H$2:$H$1031) | J40: 615.5 | K40: 48 | L40: 20 | M40: 22 | N40: =J40+K40+L40+M40 | O40: =IF(ISNUMBER(N40),N40,"") | P40: =_xlfn.RANK.EQ(O40,$O$2:$O$1031) | Q40: 252 | R40: 45 | S40: 21 | T40: 22.5 | U40: =Q40+R40+S40+T40 | V40: =IF(ISNUMBER(U40),U40,"") | W40: =_xlfn.RANK.EQ(V40,$V$2:$V$1031) | X40: 1335.4792 | Y40: 24 | Z40: 22 | AA40: 19 | AB40: =IF(ISNUMBER(X40),X40+N(Y40)+N(Z40)+N(AA40),X40) | AC40: =IF(ISNUMBER(AB40),AB40,"") | AD40: =IF(ISNUMBER(AC40),_xlfn.RANK.EQ(AC40,$AC$2:$AC$1031),"") | AE40: =IF(ISNUMBER(AF40),AF40/3630,"") | AF40: =IFERROR(C40+D40+E40+F40+J40+K40+L40+M40+Q40+R40+S40+T40+IF(ISNUMBER(X40),X40,0)+N(Y40)+N(Z40)+N(AA40),"") | AG40: =IF(ISNUMBER(AF40),AF40,"") | AH40: =IF(ISNUMBER(AG40),_xlfn.RANK.EQ(AG40,$AG$2:$AG$1031),"")
...
